<?xml version="1.0"?>

<!-- XML namespaces -->
<robot xmlns:sensor="http://playerstage.sourceforge.net/gazebo/xmlschema/#sensor"
       xmlns:controller="http://playerstage.sourceforge.net/gazebo/xmlschema/#controller"
       xmlns:interface="http://playerstage.sourceforge.net/gazebo/xmlschema/#interface"
       xmlns:xacro="http://ros.org/wiki/xacro" 
	   name="pi_robot">

	<!--
	<include filename="$(find pi_robot_description)/urdf/sensors/hokuyo_laser_gazebo.xacro" />
	-->
	
	<xacro:macro name="white">
		<material name="white">
			<color rgba="1.0 1.0 1.0 1.0"/>
		</material>
	</xacro:macro>
	
	<xacro:macro name="black">
		<material name="black">
			<color rgba="0.1 0.1 0.1 1.0"/>
		</material>
	</xacro:macro>
	
	<xacro:macro name="grey1">
		<material name="grey1">
			<color rgba="0.41 0.41 0.41 1.0"/>
		</material>
	</xacro:macro>
	
	<xacro:macro name="blue1">
		<material name="blue1">
			<color rgba="0 0 .8 1"/>
		</material>
	</xacro:macro>
	
	<xacro:macro name="green1">
		<material name="green1">
			<color rgba="0 1 0 0.5"/>
		</material>
	</xacro:macro>
	
	<xacro:macro name="red1">
	  <material name="red1">
	    <color rgba="1 0 0 0.5"/>
		</material>
	</xacro:macro>
	
	<xacro:macro name="my_box" params="name lwh xyz rpy mass material *rviz_color">
		<link name="${name}">
			<visual>
				<origin xyz="${xyz}" rpy="${rpy}" />
				<geometry>
					<box size="${lwh}" />
				</geometry>
			    <xacro:insert_block name="rviz_color" />             
             </visual>
             <collision>
				<origin xyz="${xyz}" rpy="${rpy}" />
					<geometry>
						<box size="${lwh}" />
					</geometry>
             </collision>
             <xacro:default_inertial mass="${mass}" />   
        </link>
        <xacro:default_gazebo name="${name}" material="${material}" />
	</xacro:macro>

	<xacro:macro name="my_cylinder" params="name l r xyz rpy mass material *rviz_color">
		<link name="${name}">
			<visual>
				<origin xyz="${xyz}" rpy="${rpy}" />
				<geometry>
					<cylinder length="${l}" radius="${r}"/>
				</geometry>
				<xacro:insert_block name="rviz_color" />             
			</visual>
			<collision>
				<origin xyz="${xyz}" rpy="${rpy}" />
					<geometry>
						<cylinder length="${l}" radius="${r}" />
					</geometry>
			</collision>
			<xacro:default_inertial mass="${mass}" />   
		</link>
        <xacro:default_gazebo name="${name}" material="${material}" />
	</xacro:macro>
	
    
    <xacro:macro name="default_gazebo" params="name material">
 		<gazebo reference="${name}">
			<material>${material}</material>
			<selfCollide>false</selfCollide>
			<turnGravityOff>true</turnGravityOff>
		</gazebo>
    </xacro:macro>
    
 	<!-- ============================   Body   ============================ -->
 	
 	<!--
 	<link name="world" />
 	-->

	<xacro:my_box name="base_link" lwh="0.36 0.52 0.02" xyz="0 0 0" rpy="0 0 0" mass="0.5" material="Gazebo/WhiteEmissive">
		<xacro:white />
	</xacro:my_box>
	
 	<xacro:my_box name="torso_link" lwh="0.005 0.4 0.75" xyz="0 0 0" rpy="0 0 0" mass="0.5" material="Gazebo/WhiteEmissive">
		<xacro:grey1 />
	</xacro:my_box>
	
	<xacro:my_box name="shoulder_pan_support_link" lwh="0.06 0.04 0.005" xyz="0 0 0" rpy="0 0 0" mass="0.5" material="Gazebo/WhiteEmissive">
		<xacro:blue1 />
	</xacro:my_box>
		
 	<xacro:my_cylinder name="shoulder_pan_link" l="0.2" r="0.05" xyz="0 0 0" rpy="0 0 0" mass="0.5" material="Gazebo/WhiteEmissive">
		<xacro:green1 />
	</xacro:my_cylinder>

	<xacro:my_box name="shoulder_tilt_support_link" lwh="0.035 0.003 0.04" xyz="0 0 0" rpy="0 0 0" mass="0.5" material="Gazebo/WhiteEmissive">
		<xacro:blue1 />
	</xacro:my_box>
	
	<!--xacro:my_box name="upper_arm_support_link" lwh="0.035 0.04 0.003" xyz="0 0 0" rpy="0 0 0" mass="0.5" material="Gazebo/WhiteEmissive">
		<xacro:blue1 />
	</xacro:my_box>
	
	 <xacro:my_cylinder name="upper_arm_link" l="0.27" r="0.025" xyz="0 0 0" rpy="0 0 0" mass="0.5" material="Gazebo/WhiteEmissive">
		<xacro:red1 />
	</xacro:my_cylinder-->
	
	
 	<!-- ============================   Arms   ============================ -->


	
	<!-- =================== Joint Definitions ==================== -->
	
	<!--joint name="shoulder_tilt_joint" type="revolute">
	  <parent link="shoulder_turret_link" />
	  <child link="upper_arm_link" />
	  <axis xyz="1 0 0"/>
	  <origin xyz="0 0.033 0" rpy="0 0 0" />
	  <limit lower="0.5" upper="1.0" effort="1.0" velocity="1.0" />
	</joint-->

	<joint name="shoulder_tilt_support_joint" type="fixed">
	  <parent link="shoulder_pan_link" />
	  <child link="shoulder_tilt_support_link" />
	  <origin xyz="0.0175 0.0 0" rpy="0 0 0" />
	</joint>
	
	<joint name="shoulder_pan_joint" type="continuous">
	  <parent link="shoulder_pan_support_link" />
	  <child link="shoulder_pan_link" />
	  <axis xyz="0.0 0 1"/>
	  <origin xyz="0.03 0 0" rpy="0 0 0" />
	</joint>
	
	<joint name="shoulder_pan_support_joint" type="fixed">
	  <parent link="torso_link" />
	  <child link="shoulder_pan_support_link" />
	  <origin xyz="0.0325 -0.14 0.173" rpy="0 0 0" />
	</joint>
	
	<joint name="torso_joint" type="fixed">
	  <parent link="base_link" />
	  <child link="torso_link" />
	  <origin xyz="0 0 0.375" rpy="0 0 0" />
	</joint>
	



	


  
 	

	
	<gazebo reference="maggie">
  	</gazebo>
</robot>


