<?xml version="1.0" ?>
<!-- =================================================================================== -->
<!-- |    This document was autogenerated by xacro from maggie.xacro                   | -->
<!-- |    EDITING THIS FILE BY HAND IS NOT RECOMMENDED                                 | -->
<!-- =================================================================================== -->
<!-- XML namespaces -->
<robot name="maggie" xmlns:body="http://playerstage.sourceforge.net/gazebo/xmlschema/#body" xmlns:controller="http://playerstage.sourceforge.net/gazebo/xmlschema/#controller" xmlns:geom="http://playerstage.sourceforge.net/gazebo/xmlschema/#geom" xmlns:interface="http://playerstage.sourceforge.net/gazebo/xmlschema/#interface" xmlns:joint="http://playerstage.sourceforge.net/gazebo/xmlschema/#slider" xmlns:sensor="http://playerstage.sourceforge.net/gazebo/xmlschema/#sensor" xmlns:xacro="http://ros.org/wiki/xacro">
  <material name="Blue">
    <color rgba="0.0 0.0 0.8 1.0"/>
  </material>
  <material name="Green">
    <color rgba="0.0 0.8 0.0 1.0"/>
  </material>
  <material name="Grey">
    <color rgba="0.7 0.7 0.7 1.0"/>
  </material>
  <material name="Grey2">
    <color rgba="0.9 0.9 0.9 1.0"/>
  </material>
  <material name="Red">
    <color rgba="0.8 0.0 0.0 1.0"/>
  </material>
  <material name="White">
    <color rgba="1.0 1.0 1.0 1.0"/>
  </material>
  <material name="Black">
    <color rgba="0.1 0.1 0.1 1.0"/>
  </material>
  <material name="LightGrey">
    <color rgba="0.6 0.6 0.6 1.0"/>
  </material>
  <material name="Caster">
    <texture filename="package://pr2_description/materials/textures/pr2_caster_texture.png"/>
  </material>
  <material name="Wheel_l">
    <texture filename="package://pr2_description/materials/textures/pr2_wheel_left.png"/>
  </material>
  <material name="Wheel_r">
    <texture filename="package://pr2_description/materials/textures/pr2_wheel_right.png"/>
  </material>
  <material name="RollLinks">
    <texture filename="package://pr2_description/materials/textures/pr2_wheel_left.png"/>
  </material>
  <!-- ============================   Body   ============================ -->
  <!--
 	<link name="world" />
 	-->
  <link name="base_link">
    <visual>
      <origin rpy="0 0 0" xyz="0 0 0"/>
      <geometry>
        <box size="0.36 0.52 0.02"/>
      </geometry>
      <material name="white">
        <color rgba="1.0 1.0 1.0 1.0"/>
      </material>
    </visual>
    <collision>
      <origin rpy="0 0 0" xyz="0 0 0"/>
      <geometry>
        <box size="0.36 0.52 0.02"/>
      </geometry>
    </collision>
    <xacro:default_inertial mass="0.5"/>
  </link>
  <gazebo reference="base_link">
    <material>Gazebo/WhiteEmissive</material>
    <selfCollide>false</selfCollide>
    <turnGravityOff>true</turnGravityOff>
  </gazebo>
  <link name="torso_link">
    <visual>
      <origin rpy="0 0 0" xyz="0 0 0"/>
      <geometry>
        <box size="0.005 0.4 0.752"/>
      </geometry>
      <material name="grey1">
        <color rgba="0.41 0.41 0.41 0.5"/>
      </material>
    </visual>
    <collision>
      <origin rpy="0 0 0" xyz="0 0 0"/>
      <geometry>
        <box size="0.005 0.4 0.752"/>
      </geometry>
    </collision>
    <xacro:default_inertial mass="0.5"/>
  </link>
  <gazebo reference="torso_link">
    <material>Gazebo/WhiteEmissive</material>
    <selfCollide>false</selfCollide>
    <turnGravityOff>true</turnGravityOff>
  </gazebo>
  <link name="shoulder_pan_support_link">
    <visual>
      <origin rpy="0 0 0" xyz="0 0 0"/>
      <geometry>
        <box size="0.08 0.04 0.005"/>
      </geometry>
      <material name="blue1">
        <color rgba="0 0 .8 1"/>
      </material>
    </visual>
    <collision>
      <origin rpy="0 0 0" xyz="0 0 0"/>
      <geometry>
        <box size="0.08 0.04 0.005"/>
      </geometry>
    </collision>
    <xacro:default_inertial mass="0.5"/>
  </link>
  <gazebo reference="shoulder_pan_support_link">
    <material>Gazebo/WhiteEmissive</material>
    <selfCollide>false</selfCollide>
    <turnGravityOff>true</turnGravityOff>
  </gazebo>
  <link name="shoulder_pan_link">
    <visual>
      <origin rpy="0 0 0" xyz="0 0 0"/>
      <geometry>
        <cylinder length="0.2" radius="0.05"/>
      </geometry>
      <material name="green1">
        <color rgba="0 1 0 0.5"/>
      </material>
    </visual>
    <collision>
      <origin rpy="0 0 0" xyz="0 0 0"/>
      <geometry>
        <cylinder length="0.2" radius="0.05"/>
      </geometry>
    </collision>
    <xacro:default_inertial mass="0.5"/>
  </link>
  <gazebo reference="shoulder_pan_link">
    <material>Gazebo/WhiteEmissive</material>
    <selfCollide>false</selfCollide>
    <turnGravityOff>true</turnGravityOff>
  </gazebo>
  <link name="shoulder_tilt_support_link">
    <visual>
      <origin rpy="0 0 0" xyz="0 0 0"/>
      <geometry>
        <box size="0.068 0.003 0.06"/>
      </geometry>
      <material name="blue1">
        <color rgba="0 0 .8 1"/>
      </material>
    </visual>
    <collision>
      <origin rpy="0 0 0" xyz="0 0 0"/>
      <geometry>
        <box size="0.068 0.003 0.06"/>
      </geometry>
    </collision>
    <xacro:default_inertial mass="0.5"/>
  </link>
  <gazebo reference="shoulder_tilt_support_link">
    <material>Gazebo/WhiteEmissive</material>
    <selfCollide>false</selfCollide>
    <turnGravityOff>true</turnGravityOff>
  </gazebo>
  <link name="shoulder_tilt_link">
    <visual>
      <origin rpy="0 0 0" xyz="0.05 0 0"/>
      <geometry>
        <box size="0.1 0.003 0.02"/>
      </geometry>
      <material name="red1">
        <color rgba="1 0 0 0.5"/>
      </material>
    </visual>
    <collision>
      <origin rpy="0 0 0" xyz="0.05 0 0"/>
      <geometry>
        <box size="0.1 0.003 0.02"/>
      </geometry>
    </collision>
    <xacro:default_inertial mass="0.5"/>
  </link>
  <gazebo reference="shoulder_tilt_link">
    <material>Gazebo/WhiteEmissive</material>
    <selfCollide>false</selfCollide>
    <turnGravityOff>true</turnGravityOff>
  </gazebo>
  <link name="upper_arm_link">
    <visual>
      <origin rpy="0 1.57 0" xyz="0.065 0 0"/>
      <geometry>
        <cylinder length="0.13" radius="0.025"/>
      </geometry>
      <material name="blue1">
        <color rgba="0 0 .8 1"/>
      </material>
    </visual>
    <collision>
      <origin rpy="0 1.57 0" xyz="0.065 0 0"/>
      <geometry>
        <cylinder length="0.13" radius="0.025"/>
      </geometry>
    </collision>
    <xacro:default_inertial mass="0.5"/>
  </link>
  <gazebo reference="upper_arm_link">
    <material>Gazebo/WhiteEmissive</material>
    <selfCollide>false</selfCollide>
    <turnGravityOff>true</turnGravityOff>
  </gazebo>
  <link name="elbow_tilt_link">
    <visual>
      <origin rpy="0 0 0" xyz="0.05 0 0"/>
      <geometry>
        <box size="0.1 0.003 0.03"/>
      </geometry>
      <material name="green1">
        <color rgba="0 1 0 0.5"/>
      </material>
    </visual>
    <collision>
      <origin rpy="0 0 0" xyz="0.05 0 0"/>
      <geometry>
        <box size="0.1 0.003 0.03"/>
      </geometry>
    </collision>
    <xacro:default_inertial mass="0.5"/>
  </link>
  <gazebo reference="elbow_tilt_link">
    <material>Gazebo/WhiteEmissive</material>
    <selfCollide>false</selfCollide>
    <turnGravityOff>true</turnGravityOff>
  </gazebo>
  <link name="forearm_link">
    <visual>
      <origin rpy="0 1.57 0" xyz="0.075 0 0"/>
      <geometry>
        <cylinder length="0.151" radius="0.025"/>
      </geometry>
      <material name="grey1">
        <color rgba="0.41 0.41 0.41 0.5"/>
      </material>
    </visual>
    <collision>
      <origin rpy="0 1.57 0" xyz="0.075 0 0"/>
      <geometry>
        <cylinder length="0.151" radius="0.025"/>
      </geometry>
    </collision>
    <xacro:default_inertial mass="0.5"/>
  </link>
  <gazebo reference="forearm_link">
    <material>Gazebo/WhiteEmissive</material>
    <selfCollide>false</selfCollide>
    <turnGravityOff>true</turnGravityOff>
  </gazebo>
  <link name="wrist_tilt_link">
    <visual>
      <origin rpy="0 0 0" xyz="0.018 0 0"/>
      <geometry>
        <box size="0.036 0.003 0.03"/>
      </geometry>
      <material name="blue1">
        <color rgba="0 0 .8 1"/>
      </material>
    </visual>
    <collision>
      <origin rpy="0 0 0" xyz="0.018 0 0"/>
      <geometry>
        <box size="0.036 0.003 0.03"/>
      </geometry>
    </collision>
    <xacro:default_inertial mass="0.5"/>
  </link>
  <gazebo reference="wrist_tilt_link">
    <material>Gazebo/WhiteEmissive</material>
    <selfCollide>false</selfCollide>
    <turnGravityOff>true</turnGravityOff>
  </gazebo>
  <link name="wrist_roll_link">
    <visual>
      <origin rpy="0 0 0" xyz="0.0175 0 0"/>
      <geometry>
        <box size="0.035 0.003 0.03"/>
      </geometry>
      <material name="red1">
        <color rgba="1 0 0 0.5"/>
      </material>
    </visual>
    <collision>
      <origin rpy="0 0 0" xyz="0.0175 0 0"/>
      <geometry>
        <box size="0.035 0.003 0.03"/>
      </geometry>
    </collision>
    <xacro:default_inertial mass="0.5"/>
  </link>
  <gazebo reference="wrist_roll_link">
    <material>Gazebo/WhiteEmissive</material>
    <selfCollide>false</selfCollide>
    <turnGravityOff>true</turnGravityOff>
  </gazebo>
  <link name="hand_link">
    <visual>
      <origin rpy="0 0 0" xyz="0.005 0 0"/>
      <geometry>
        <box size="0.01 0.01 0.005"/>
      </geometry>
      <material name="green1">
        <color rgba="0 1 0 0.5"/>
      </material>
    </visual>
    <collision>
      <origin rpy="0 0 0" xyz="0.005 0 0"/>
      <geometry>
        <box size="0.01 0.01 0.005"/>
      </geometry>
    </collision>
    <xacro:default_inertial mass="0.001"/>
  </link>
  <gazebo reference="hand_link">
    <material>Gazebo/WhiteEmissive</material>
    <selfCollide>false</selfCollide>
    <turnGravityOff>true</turnGravityOff>
  </gazebo>
  <!--	<xacro:my_box name="hand_link" lwh="0.03 0.01 0.064" xyz="0 0 -0.032" rpy="0 0 0" mass="0.1" material="Gazebo/WhiteEmissive">
	  <xacro:grey1 />
	</xacro:my_box>-->
  <!--	<xacro:my_box name="finger_link" lwh="0.01 0.01 0.005" xyz="0 0 0" rpy="0 0 0" mass="0.001" material="Gazebo/WhiteEmissive">
	  <xacro:green1 />
	</xacro:my_box>-->
  <!--xacro:pr2_gripper_v0 reflect="-1.0" side="r" parent="wrist_roll_link"
               screw_reduction="${4.0/1000.0}"
               gear_ratio="${(729.0/25.0)*(22.0/16.0)}"
               theta0="${3.6029*M_PI/180.0}"
               phi0="${29.7089*M_PI/180.0}"
               t0="${-0.1914/1000.0}"
               L0="${37.5528/1000.0}"
               h="${0.0/1000.0}"
               a="${68.3698/1000.0}"
               b="${43.3849/1000.0}"
               r="${91.5/1000.0}" >
	<origin xyz="0 0 0" rpy="0 0 0" />
      </xacro:pr2_gripper_v0-->
  <!-- head links -->
  <link name="lower_neck_link">
    <visual>
      <origin rpy="0 0 0" xyz="0 0 0.079"/>
      <geometry>
        <cylinder length="0.16" radius="0.025"/>
      </geometry>
      <material name="grey1">
        <color rgba="0.41 0.41 0.41 0.5"/>
      </material>
    </visual>
    <collision>
      <origin rpy="0 0 0" xyz="0 0 0.079"/>
      <geometry>
        <cylinder length="0.16" radius="0.025"/>
      </geometry>
    </collision>
    <xacro:default_inertial mass="0.05"/>
  </link>
  <gazebo reference="lower_neck_link">
    <material>Gazebo/WhiteEmissive</material>
    <selfCollide>false</selfCollide>
    <turnGravityOff>true</turnGravityOff>
  </gazebo>
  <!--	<xacro:my_box name="upper_neck_link" lwh="0.026 0.048 0.026" xyz="0 0 0.013" rpy="0 0 0" mass="0.05" material="Gazebo/WhiteEmissive">
		<xacro:bracket_color />
	</xacro:my_box>-->
  <link name="head_pan_servo_link">
    <visual>
      <origin rpy="0 0 0" xyz="-0.01 0 0.022"/>
      <geometry>
        <box size="0.05 0.035 0.044"/>
      </geometry>
      <material name="ax12_color">
        <color rgba="0.1 0.1 0.1 1.0"/>
      </material>
    </visual>
    <collision>
      <origin rpy="0 0 0" xyz="-0.01 0 0.022"/>
      <geometry>
        <box size="0.05 0.035 0.044"/>
      </geometry>
    </collision>
    <xacro:default_inertial mass="0.055"/>
  </link>
  <gazebo reference="head_pan_servo_link">
    <material>Gazebo/FlatBlack</material>
    <selfCollide>false</selfCollide>
    <turnGravityOff>true</turnGravityOff>
  </gazebo>
  <link name="head_pan_link">
    <visual>
      <origin rpy="0 0 0" xyz="-0.01 0 0.022"/>
      <geometry>
        <box size="0.05 0.035 0.044"/>
      </geometry>
      <material name="ax12_color">
        <color rgba="0.1 0.1 0.1 1.0"/>
      </material>
    </visual>
    <collision>
      <origin rpy="0 0 0" xyz="-0.01 0 0.022"/>
      <geometry>
        <box size="0.05 0.035 0.044"/>
      </geometry>
    </collision>
    <xacro:default_inertial mass="0.055"/>
  </link>
  <gazebo reference="head_pan_link">
    <material>Gazebo/FlatBlack</material>
    <selfCollide>false</selfCollide>
    <turnGravityOff>true</turnGravityOff>
  </gazebo>
  <link name="head_tilt_link">
    <visual>
      <origin rpy="0 0 0" xyz="0 0 0.015"/>
      <geometry>
        <box size="0.03 0.038 0.030"/>
      </geometry>
      <material name="ax12_color">
        <color rgba="0.1 0.1 0.1 1.0"/>
      </material>
    </visual>
    <collision>
      <origin rpy="0 0 0" xyz="0 0 0.015"/>
      <geometry>
        <box size="0.03 0.038 0.030"/>
      </geometry>
    </collision>
    <xacro:default_inertial mass="0.055"/>
  </link>
  <gazebo reference="head_tilt_link">
    <material>Gazebo/FlatBlack</material>
    <selfCollide>false</selfCollide>
    <turnGravityOff>true</turnGravityOff>
  </gazebo>
  <link name="head_base_link">
    <visual>
      <origin rpy="0 0 0" xyz="0 0 0.011"/>
      <geometry>
        <box size="0.06 0.08 0.022"/>
      </geometry>
      <material name="black">
        <color rgba="0.1 0.1 0.1 1.0"/>
      </material>
    </visual>
    <collision>
      <origin rpy="0 0 0" xyz="0 0 0.011"/>
      <geometry>
        <box size="0.06 0.08 0.022"/>
      </geometry>
    </collision>
    <xacro:default_inertial mass="0.1"/>
  </link>
  <gazebo reference="head_base_link">
    <material>Gazebo/FlatBlack</material>
    <selfCollide>false</selfCollide>
    <turnGravityOff>true</turnGravityOff>
  </gazebo>
  <link name="head_post_link">
    <visual>
      <origin rpy="0 0 0" xyz="0 0 0.011"/>
      <geometry>
        <cylinder length="0.012" radius="0.005"/>
      </geometry>
      <material name="grey1">
        <color rgba="0.41 0.41 0.41 0.5"/>
      </material>
    </visual>
    <collision>
      <origin rpy="0 0 0" xyz="0 0 0.011"/>
      <geometry>
        <cylinder length="0.012" radius="0.005"/>
      </geometry>
    </collision>
    <xacro:default_inertial mass="0.1"/>
  </link>
  <gazebo reference="head_post_link">
    <material>Gazebo/WhiteEmissive</material>
    <selfCollide>false</selfCollide>
    <turnGravityOff>true</turnGravityOff>
  </gazebo>
  <link name="head_link">
    <visual>
      <origin rpy="0 0 0" xyz="0 0 0.0175"/>
      <geometry>
        <box size="0.06 0.26 0.035"/>
      </geometry>
      <material name="black">
        <color rgba="0.1 0.1 0.1 1.0"/>
      </material>
    </visual>
    <collision>
      <origin rpy="0 0 0" xyz="0 0 0.0175"/>
      <geometry>
        <box size="0.06 0.26 0.035"/>
      </geometry>
    </collision>
    <xacro:default_inertial mass="0.8"/>
  </link>
  <gazebo reference="head_link">
    <material>Gazebo/FlatBlack</material>
    <selfCollide>false</selfCollide>
    <turnGravityOff>true</turnGravityOff>
  </gazebo>
  <link name="left_eye_link">
    <visual>
      <origin rpy="0 0 0" xyz="0 0 0.005"/>
      <geometry>
        <cylinder length="0.01" radius="0.01"/>
      </geometry>
      <material name="grey1">
        <color rgba="0.41 0.41 0.41 0.5"/>
      </material>
    </visual>
    <collision>
      <origin rpy="0 0 0" xyz="0 0 0.005"/>
      <geometry>
        <cylinder length="0.01" radius="0.01"/>
      </geometry>
    </collision>
    <xacro:default_inertial mass="0.001"/>
  </link>
  <gazebo reference="left_eye_link">
    <material>Gazebo/WhiteEmissive</material>
    <selfCollide>false</selfCollide>
    <turnGravityOff>true</turnGravityOff>
  </gazebo>
  <link name="right_eye_link">
    <visual>
      <origin rpy="0 0 0" xyz="0 0 0.005"/>
      <geometry>
        <cylinder length="0.01" radius="0.01"/>
      </geometry>
      <material name="grey1">
        <color rgba="0.41 0.41 0.41 0.5"/>
      </material>
    </visual>
    <collision>
      <origin rpy="0 0 0" xyz="0 0 0.005"/>
      <geometry>
        <cylinder length="0.01" radius="0.01"/>
      </geometry>
    </collision>
    <xacro:default_inertial mass="0.001"/>
  </link>
  <gazebo reference="right_eye_link">
    <material>Gazebo/WhiteEmissive</material>
    <selfCollide>false</selfCollide>
    <turnGravityOff>true</turnGravityOff>
  </gazebo>
  <!-- ============================   Arms   ============================ -->
  <!-- =================== Joint Definitions ==================== -->
  <!-- head joints -->
  <joint name="lower_neck_joint" type="fixed">
    <parent link="torso_link"/>
    <child link="lower_neck_link"/>
    <origin rpy="0 0 0" xyz="-0.0275 0 0.376"/>
  </joint>
  <joint name="head_pan_servo_joint" type="fixed">
    <parent link="lower_neck_link"/>
    <child link="head_pan_servo_link"/>
    <origin rpy="0 0 0" xyz="0.029 0 0.16"/>
  </joint>
  <joint name="head_pan_joint" type="revolute">
    <parent link="head_pan_servo_link"/>
    <child link="head_pan_link"/>
    <origin rpy="0 0 0" xyz="0 0 0.044"/>
    <axis xyz="0 0 1"/>
    <limit effort="10" lower="-3.1416" upper="3.1416" velocity="3"/>
    <dynamics damping="0.0"/>
  </joint>
  <joint name="head_tilt_joint" type="revolute">
    <parent link="head_pan_link"/>
    <child link="head_tilt_link"/>
    <origin rpy="0 0 0" xyz="0 0 0.044"/>
    <axis xyz="0 1 0"/>
    <limit effort="10" lower="-1.57" upper="1.57" velocity="3"/>
    <dynamics damping="0.0"/>
  </joint>
  <joint name="upper_neck_joint" type="fixed">
    <parent link="head_tilt_link"/>
    <child link="head_base_link"/>
    <origin rpy="0 0 0" xyz="0 0 0.030"/>
  </joint>
  <joint name="head_base_joint" type="fixed">
    <parent link="head_base_link"/>
    <child link="head_post_link"/>
    <origin rpy="0 0 0" xyz="0 0 0.022"/>
  </joint>
  <joint name="head_joint" type="fixed">
    <parent link="head_post_link"/>
    <child link="head_link"/>
    <origin rpy="0 0 0" xyz="0 0 0.012"/>
  </joint>
  <joint name="left_eye_joint" type="fixed">
    <parent link="head_link"/>
    <child link="left_eye_link"/>
    <origin rpy="0 1.57 0" xyz="0.026 0.05 0"/>
  </joint>
  <joint name="right_eye_joint" type="fixed">
    <parent link="head_link"/>
    <child link="right_eye_link"/>
    <origin rpy="0 1.57 0" xyz="0.026 -0.05 0"/>
  </joint>
  <!-- Arm Joints -->
  <joint name="hand_joint" type="fixed">
    <parent link="wrist_roll_link"/>
    <child link="hand_link"/>
    <origin rpy="0 0 0" xyz="0.0351 0 0"/>
  </joint>
  <joint name="wrist_roll_joint" type="revolute">
    <parent link="wrist_tilt_link"/>
    <child link="wrist_roll_link"/>
    <axis xyz="1 0 0"/>
    <origin rpy="0 0 0" xyz="0.0351 0 0"/>
    <limit effort="1.0" lower="-2.61" upper="2.61" velocity="1.0"/>
  </joint>
  <joint name="wrist_tilt_joint" type="revolute">
    <parent link="forearm_link"/>
    <child link="wrist_tilt_link"/>
    <axis xyz="0 1 0"/>
    <origin rpy="0 0 0" xyz="0.152 0 0.002"/>
    <limit effort="1.0" lower="-1.57" upper="1.57" velocity="1.0"/>
  </joint>
  <joint name="forearm_roll_joint" type="revolute">
    <parent link="elbow_tilt_link"/>
    <child link="forearm_link"/>
    <axis xyz="1 0 0"/>
    <origin rpy="0 0 0" xyz="0.1 0 0.012"/>
    <limit effort="1.0" lower="-2.61" upper="2.61" velocity="1.0"/>
  </joint>
  <joint name="elbow_tilt_joint" type="revolute">
    <parent link="upper_arm_link"/>
    <child link="elbow_tilt_link"/>
    <axis xyz="0 1 0"/>
    <origin rpy="0 -1.57 0" xyz="0.129 0 0"/>
    <limit effort="1.0" lower="-2.61" upper="2.61" velocity="1.0"/>
  </joint>
  <joint name="upper_arm_roll_joint" type="revolute">
    <parent link="shoulder_tilt_link"/>
    <child link="upper_arm_link"/>
    <axis xyz="1 0 0"/>
    <origin rpy="0 0 0" xyz="0.1 0 0.025"/>
    <limit effort="1.0" lower="-2.61" upper="2.61" velocity="1.0"/>
  </joint>
  <joint name="shoulder_tilt_joint" type="revolute">
    <parent link="shoulder_tilt_support_link"/>
    <child link="shoulder_tilt_link"/>
    <axis xyz="0 1 0"/>
    <origin rpy="0 0 0" xyz="0.034 -0.05 0"/>
    <limit effort="1.0" lower="-1.57" upper="1.57" velocity="1.0"/>
  </joint>
  <joint name="shoulder_tilt_support_joint" type="fixed">
    <parent link="shoulder_pan_link"/>
    <child link="shoulder_tilt_support_link"/>
    <origin rpy="0 0 0" xyz="0.034 0.05 0.05"/>
  </joint>
  <joint name="shoulder_pan_joint" type="revolute">
    <parent link="shoulder_pan_support_link"/>
    <child link="shoulder_pan_link"/>
    <axis xyz="0.0 0 1"/>
    <origin rpy="0 0 0" xyz="0.04 0 0"/>
    <limit effort="1.0" lower="-1.57" upper="1.57" velocity="1.0"/>
  </joint>
  <joint name="shoulder_pan_support_joint" type="fixed">
    <parent link="torso_link"/>
    <child link="shoulder_pan_support_link"/>
    <origin rpy="0 0 0" xyz="0.0425 -0.14 0.175"/>
  </joint>
  <joint name="torso_joint" type="fixed">
    <parent link="base_link"/>
    <child link="torso_link"/>
    <origin rpy="0 0 0" xyz="0 0 0.376"/>
  </joint>
  <gazebo reference="maggie">
  	</gazebo>
</robot>
