<?xml version="1.0" ?>
<!-- =================================================================================== -->
<!-- |    This document was autogenerated by xacro from maggie.xacro                   | -->
<!-- |    EDITING THIS FILE BY HAND IS NOT RECOMMENDED                                 | -->
<!-- =================================================================================== -->
<!-- XML namespaces -->
<robot name="pi_robot" xmlns:controller="http://playerstage.sourceforge.net/gazebo/xmlschema/#controller" xmlns:interface="http://playerstage.sourceforge.net/gazebo/xmlschema/#interface" xmlns:sensor="http://playerstage.sourceforge.net/gazebo/xmlschema/#sensor" xmlns:xacro="http://ros.org/wiki/xacro">
  <!--
	<include filename="$(find pi_robot_description)/urdf/sensors/hokuyo_laser_gazebo.xacro" />
	-->
  <!-- ============================   Body   ============================ -->
  <!--
 	<link name="world" />
 	-->
  <link name="base_link">
    <visual>
      <origin rpy="0 0 0" xyz="0 0 0"/>
      <geometry>
        <box size="0.36 0.52 0.02"/>
      </geometry>
      <material name="white">
        <color rgba="1.0 1.0 1.0 1.0"/>
      </material>
    </visual>
    <collision>
      <origin rpy="0 0 0" xyz="0 0 0"/>
      <geometry>
        <box size="0.36 0.52 0.02"/>
      </geometry>
    </collision>
    <xacro:default_inertial mass="0.5"/>
  </link>
  <gazebo reference="base_link">
    <material>Gazebo/WhiteEmissive</material>
    <selfCollide>false</selfCollide>
    <turnGravityOff>true</turnGravityOff>
  </gazebo>
  <link name="torso_link">
    <visual>
      <origin rpy="0 0 0" xyz="0 0 0"/>
      <geometry>
        <box size="0.005 0.4 0.75"/>
      </geometry>
      <material name="grey1">
        <color rgba="0.41 0.41 0.41 1.0"/>
      </material>
    </visual>
    <collision>
      <origin rpy="0 0 0" xyz="0 0 0"/>
      <geometry>
        <box size="0.005 0.4 0.75"/>
      </geometry>
    </collision>
    <xacro:default_inertial mass="0.5"/>
  </link>
  <gazebo reference="torso_link">
    <material>Gazebo/WhiteEmissive</material>
    <selfCollide>false</selfCollide>
    <turnGravityOff>true</turnGravityOff>
  </gazebo>
  <link name="shoulder_pan_support_link">
    <visual>
      <origin rpy="0 0 0" xyz="0 0 0"/>
      <geometry>
        <box size="0.06 0.04 0.005"/>
      </geometry>
      <material name="blue1">
        <color rgba="0 0 .8 1"/>
      </material>
    </visual>
    <collision>
      <origin rpy="0 0 0" xyz="0 0 0"/>
      <geometry>
        <box size="0.06 0.04 0.005"/>
      </geometry>
    </collision>
    <xacro:default_inertial mass="0.5"/>
  </link>
  <gazebo reference="shoulder_pan_support_link">
    <material>Gazebo/WhiteEmissive</material>
    <selfCollide>false</selfCollide>
    <turnGravityOff>true</turnGravityOff>
  </gazebo>
  <link name="shoulder_pan_link">
    <visual>
      <origin rpy="0 0 0" xyz="0 0 0"/>
      <geometry>
        <cylinder length="0.2" radius="0.05"/>
      </geometry>
      <material name="green1">
        <color rgba="0 1 0 0.5"/>
      </material>
    </visual>
    <collision>
      <origin rpy="0 0 0" xyz="0 0 0"/>
      <geometry>
        <cylinder length="0.2" radius="0.05"/>
      </geometry>
    </collision>
    <xacro:default_inertial mass="0.5"/>
  </link>
  <gazebo reference="shoulder_pan_link">
    <material>Gazebo/WhiteEmissive</material>
    <selfCollide>false</selfCollide>
    <turnGravityOff>true</turnGravityOff>
  </gazebo>
  <link name="shoulder_tilt_support_link">
    <visual>
      <origin rpy="0 0 0" xyz="0 0 0"/>
      <geometry>
        <box size="0.035 0.003 0.04"/>
      </geometry>
      <material name="blue1">
        <color rgba="0 0 .8 1"/>
      </material>
    </visual>
    <collision>
      <origin rpy="0 0 0" xyz="0 0 0"/>
      <geometry>
        <box size="0.035 0.003 0.04"/>
      </geometry>
    </collision>
    <xacro:default_inertial mass="0.5"/>
  </link>
  <gazebo reference="shoulder_tilt_support_link">
    <material>Gazebo/WhiteEmissive</material>
    <selfCollide>false</selfCollide>
    <turnGravityOff>true</turnGravityOff>
  </gazebo>
  <link name="shoulder_tilt_link">
    <visual>
      <origin rpy="0 0 0" xyz="0 0 -0.015"/>
      <geometry>
        <box size="0.01 0.003 0.03"/>
      </geometry>
      <material name="red1">
        <color rgba="1 0 0 0.5"/>
      </material>
    </visual>
    <collision>
      <origin rpy="0 0 0" xyz="0 0 -0.015"/>
      <geometry>
        <box size="0.01 0.003 0.03"/>
      </geometry>
    </collision>
    <xacro:default_inertial mass="0.5"/>
  </link>
  <gazebo reference="shoulder_tilt_link">
    <material>Gazebo/WhiteEmissive</material>
    <selfCollide>false</selfCollide>
    <turnGravityOff>true</turnGravityOff>
  </gazebo>
  <link name="upper_arm_link">
    <visual>
      <origin rpy="0 1.57 0" xyz="0.135 0 0"/>
      <geometry>
        <cylinder length="0.27" radius="0.025"/>
      </geometry>
      <material name="red1">
        <color rgba="1 0 0 0.5"/>
      </material>
    </visual>
    <collision>
      <origin rpy="0 1.57 0" xyz="0.135 0 0"/>
      <geometry>
        <cylinder length="0.27" radius="0.025"/>
      </geometry>
    </collision>
    <xacro:default_inertial mass="0.5"/>
  </link>
  <gazebo reference="upper_arm_link">
    <material>Gazebo/WhiteEmissive</material>
    <selfCollide>false</selfCollide>
    <turnGravityOff>true</turnGravityOff>
  </gazebo>
  <link name="elbow_tilt_link">
    <visual>
      <origin rpy="0 0 0" xyz="0.005 0 0"/>
      <geometry>
        <box size="0.01 0.003 0.03"/>
      </geometry>
      <material name="blue1">
        <color rgba="0 0 .8 1"/>
      </material>
    </visual>
    <collision>
      <origin rpy="0 0 0" xyz="0.005 0 0"/>
      <geometry>
        <box size="0.01 0.003 0.03"/>
      </geometry>
    </collision>
    <xacro:default_inertial mass="0.5"/>
  </link>
  <gazebo reference="elbow_tilt_link">
    <material>Gazebo/WhiteEmissive</material>
    <selfCollide>false</selfCollide>
    <turnGravityOff>true</turnGravityOff>
  </gazebo>
  <link name="forearm_link">
    <visual>
      <origin rpy="0 1.57 0" xyz="0.135 0 0"/>
      <geometry>
        <cylinder length="0.27" radius="0.025"/>
      </geometry>
      <material name="red1">
        <color rgba="1 0 0 0.5"/>
      </material>
    </visual>
    <collision>
      <origin rpy="0 1.57 0" xyz="0.135 0 0"/>
      <geometry>
        <cylinder length="0.27" radius="0.025"/>
      </geometry>
    </collision>
    <xacro:default_inertial mass="0.5"/>
  </link>
  <gazebo reference="forearm_link">
    <material>Gazebo/WhiteEmissive</material>
    <selfCollide>false</selfCollide>
    <turnGravityOff>true</turnGravityOff>
  </gazebo>
  <!-- head links -->
  <link name="lower_neck_link">
    <visual>
      <origin rpy="0 0 0" xyz="0 0 0"/>
      <geometry>
        <cylinder length="0.16" radius="0.025"/>
      </geometry>
      <material name="grey1">
        <color rgba="0.41 0.41 0.41 1.0"/>
      </material>
    </visual>
    <collision>
      <origin rpy="0 0 0" xyz="0 0 0"/>
      <geometry>
        <cylinder length="0.16" radius="0.025"/>
      </geometry>
    </collision>
    <xacro:default_inertial mass="0.05"/>
  </link>
  <gazebo reference="lower_neck_link">
    <material>Gazebo/WhiteEmissive</material>
    <selfCollide>false</selfCollide>
    <turnGravityOff>true</turnGravityOff>
  </gazebo>
  <link name="upper_neck_link">
    <visual>
      <origin rpy="0 0 0" xyz="0 0 0.01"/>
      <geometry>
        <box size="0.028 0.048 0.037"/>
      </geometry>
      <material name="bracket_color">
        <color rgba="0.9 0.9 0.9 1.0"/>
      </material>
    </visual>
    <collision>
      <origin rpy="0 0 0" xyz="0 0 0.01"/>
      <geometry>
        <box size="0.028 0.048 0.037"/>
      </geometry>
    </collision>
    <xacro:default_inertial mass="0.05"/>
  </link>
  <gazebo reference="upper_neck_link">
    <material>Gazebo/WhiteEmissive</material>
    <selfCollide>false</selfCollide>
    <turnGravityOff>true</turnGravityOff>
  </gazebo>
  <link name="head_pan_link">
    <visual>
      <origin rpy="0 0 0" xyz="0 0 0"/>
      <geometry>
        <box size="0.05 0.035 0.04"/>
      </geometry>
      <material name="ax12_color">
        <color rgba="0.1 0.1 0.1 1.0"/>
      </material>
    </visual>
    <collision>
      <origin rpy="0 0 0" xyz="0 0 0"/>
      <geometry>
        <box size="0.05 0.035 0.04"/>
      </geometry>
    </collision>
    <xacro:default_inertial mass="0.055"/>
  </link>
  <gazebo reference="head_pan_link">
    <material>Gazebo/FlatBlack</material>
    <selfCollide>false</selfCollide>
    <turnGravityOff>true</turnGravityOff>
  </gazebo>
  <link name="head_tilt_link">
    <visual>
      <origin rpy="0 0 0" xyz="0 0 0"/>
      <geometry>
        <box size="0.03 0.038 0.057"/>
      </geometry>
      <material name="ax12_color">
        <color rgba="0.1 0.1 0.1 1.0"/>
      </material>
    </visual>
    <collision>
      <origin rpy="0 0 0" xyz="0 0 0"/>
      <geometry>
        <box size="0.03 0.038 0.057"/>
      </geometry>
    </collision>
    <xacro:default_inertial mass="0.055"/>
  </link>
  <gazebo reference="head_tilt_link">
    <material>Gazebo/FlatBlack</material>
    <selfCollide>false</selfCollide>
    <turnGravityOff>true</turnGravityOff>
  </gazebo>
  <link name="head_base_link">
    <visual>
      <origin rpy="0 0 0" xyz="0 0 00"/>
      <geometry>
        <box size="0.06 0.08 0.022"/>
      </geometry>
      <material name="black">
        <color rgba="0.1 0.1 0.1 1.0"/>
      </material>
    </visual>
    <collision>
      <origin rpy="0 0 0" xyz="0 0 00"/>
      <geometry>
        <box size="0.06 0.08 0.022"/>
      </geometry>
    </collision>
    <xacro:default_inertial mass="0.1"/>
  </link>
  <gazebo reference="head_base_link">
    <material>Gazebo/FlatBlack</material>
    <selfCollide>false</selfCollide>
    <turnGravityOff>true</turnGravityOff>
  </gazebo>
  <link name="head_post_link">
    <visual>
      <origin rpy="0 0 0" xyz="0 0 00"/>
      <geometry>
        <cylinder length="0.012" radius="0.005"/>
      </geometry>
      <material name="grey1">
        <color rgba="0.41 0.41 0.41 1.0"/>
      </material>
    </visual>
    <collision>
      <origin rpy="0 0 0" xyz="0 0 00"/>
      <geometry>
        <cylinder length="0.012" radius="0.005"/>
      </geometry>
    </collision>
    <xacro:default_inertial mass="0.1"/>
  </link>
  <gazebo reference="head_post_link">
    <material>Gazebo/WhiteEmissive</material>
    <selfCollide>false</selfCollide>
    <turnGravityOff>true</turnGravityOff>
  </gazebo>
  <link name="head_link">
    <visual>
      <origin rpy="0 0 0" xyz="0 0 00"/>
      <geometry>
        <box size="0.06 0.26 0.035"/>
      </geometry>
      <material name="black">
        <color rgba="0.1 0.1 0.1 1.0"/>
      </material>
    </visual>
    <collision>
      <origin rpy="0 0 0" xyz="0 0 00"/>
      <geometry>
        <box size="0.06 0.26 0.035"/>
      </geometry>
    </collision>
    <xacro:default_inertial mass="0.8"/>
  </link>
  <gazebo reference="head_link">
    <material>Gazebo/FlatBlack</material>
    <selfCollide>false</selfCollide>
    <turnGravityOff>true</turnGravityOff>
  </gazebo>
  <link name="left_eye_link">
    <visual>
      <origin rpy="0 0 0" xyz="0 0 00"/>
      <geometry>
        <cylinder length="0.01" radius="0.01"/>
      </geometry>
      <material name="grey1">
        <color rgba="0.41 0.41 0.41 1.0"/>
      </material>
    </visual>
    <collision>
      <origin rpy="0 0 0" xyz="0 0 00"/>
      <geometry>
        <cylinder length="0.01" radius="0.01"/>
      </geometry>
    </collision>
    <xacro:default_inertial mass="0.001"/>
  </link>
  <gazebo reference="left_eye_link">
    <material>Gazebo/WhiteEmissive</material>
    <selfCollide>false</selfCollide>
    <turnGravityOff>true</turnGravityOff>
  </gazebo>
  <link name="right_eye_link">
    <visual>
      <origin rpy="0 0 0" xyz="0 0 00"/>
      <geometry>
        <cylinder length="0.01" radius="0.01"/>
      </geometry>
      <material name="grey1">
        <color rgba="0.41 0.41 0.41 1.0"/>
      </material>
    </visual>
    <collision>
      <origin rpy="0 0 0" xyz="0 0 00"/>
      <geometry>
        <cylinder length="0.01" radius="0.01"/>
      </geometry>
    </collision>
    <xacro:default_inertial mass="0.001"/>
  </link>
  <gazebo reference="right_eye_link">
    <material>Gazebo/WhiteEmissive</material>
    <selfCollide>false</selfCollide>
    <turnGravityOff>true</turnGravityOff>
  </gazebo>
  <!-- ============================   Arms   ============================ -->
  <!-- =================== Joint Definitions ==================== -->
  <!-- head joints -->
  <joint name="lower_neck_joint" type="fixed">
    <parent link="torso_link"/>
    <child link="lower_neck_link"/>
    <origin rpy="0 0 0" xyz="-0.0275 0 0.455"/>
  </joint>
  <joint name="head_pan_servo_joint" type="fixed">
    <parent link="lower_neck_link"/>
    <child link="head_pan_link"/>
    <origin rpy="0 0 0" xyz="0.02 0 0.1"/>
  </joint>
  <joint name="head_pan_joint" type="revolute">
    <parent link="head_pan_link"/>
    <child link="head_tilt_link"/>
    <origin rpy="0 0 0" xyz="0.01 0 0.048"/>
    <axis xyz="0 0 1"/>
    <limit effort="10" lower="-3.1416" upper="3.1416" velocity="3"/>
    <dynamics damping="0.0"/>
  </joint>
  <joint name="head_tilt_joint" type="revolute">
    <parent link="head_tilt_link"/>
    <child link="upper_neck_link"/>
    <origin rpy="0 0 0" xyz="0 0 0.013"/>
    <axis xyz="0 1 0"/>
    <limit effort="10" lower="-1.57" upper="1.57" velocity="3"/>
    <dynamics damping="0.0"/>
  </joint>
  <joint name="upper_neck_joint" type="fixed">
    <parent link="upper_neck_link"/>
    <child link="head_base_link"/>
    <origin rpy="0 0 0" xyz="0 0 0.040"/>
  </joint>
  <joint name="head_base_joint" type="fixed">
    <parent link="head_base_link"/>
    <child link="head_post_link"/>
    <origin rpy="0 0 0" xyz="0 0 0.016"/>
  </joint>
  <joint name="head_joint" type="fixed">
    <parent link="head_post_link"/>
    <child link="head_link"/>
    <origin rpy="0 0 0" xyz="0 0 0.0235"/>
  </joint>
  <joint name="left_eye_joint" type="fixed">
    <parent link="head_link"/>
    <child link="left_eye_link"/>
    <origin rpy="0 1.57 0" xyz="0.026 0.05 0"/>
  </joint>
  <joint name="right_eye_joint" type="fixed">
    <parent link="head_link"/>
    <child link="right_eye_link"/>
    <origin rpy="0 1.57 0" xyz="0.026 -0.05 0"/>
  </joint>
  <!-- arm joints -->
  <joint name="forearm_roll_joint" type="revolute">
    <parent link="elbow_tilt_link"/>
    <child link="forearm_link"/>
    <axis xyz="0.135 0 0"/>
    <origin rpy="0 0 0" xyz="0 0 0"/>
    <limit effort="1.0" lower="-1.0" upper="1.0" velocity="1.0"/>
  </joint>
  <joint name="elbow_tilt_joint" type="revolute">
    <parent link="upper_arm_link"/>
    <child link="elbow_tilt_link"/>
    <axis xyz="0 1 0"/>
    <origin rpy="0 0 0" xyz="0.27 0 0"/>
    <limit effort="1.0" lower="-1.0" upper="1.0" velocity="1.0"/>
  </joint>
  <joint name="upper_arm_roll_joint" type="revolute">
    <parent link="shoulder_tilt_link"/>
    <child link="upper_arm_link"/>
    <axis xyz="0.135 0 0"/>
    <origin rpy="0 0 0" xyz="0 0 0"/>
    <limit effort="1.0" lower="-1.0" upper="1.0" velocity="1.0"/>
  </joint>
  <joint name="shoulder_tilt_joint" type="revolute">
    <parent link="shoulder_tilt_support_link"/>
    <child link="shoulder_tilt_link"/>
    <axis xyz="0 1 0"/>
    <origin rpy="0 0 0" xyz="0 0 -0.015"/>
    <limit effort="1.0" lower="-1.0" upper="1.0" velocity="1.0"/>
  </joint>
  <joint name="shoulder_tilt_support_joint" type="fixed">
    <parent link="shoulder_pan_link"/>
    <child link="shoulder_tilt_support_link"/>
    <origin rpy="0 0 0" xyz="0.0175 0.0 0"/>
  </joint>
  <joint name="shoulder_pan_joint" type="revolute">
    <parent link="shoulder_pan_support_link"/>
    <child link="shoulder_pan_link"/>
    <axis xyz="0.0 0 1"/>
    <origin rpy="0 0 0" xyz="0.03 0 0"/>
    <limit effort="1.0" lower="-1.0" upper="1.0" velocity="1.0"/>
  </joint>
  <joint name="shoulder_pan_support_joint" type="fixed">
    <parent link="torso_link"/>
    <child link="shoulder_pan_support_link"/>
    <origin rpy="0 0 0" xyz="0.0325 -0.14 0.173"/>
  </joint>
  <joint name="torso_joint" type="fixed">
    <parent link="base_link"/>
    <child link="torso_link"/>
    <origin rpy="0 0 0" xyz="0 0 0.375"/>
  </joint>
  <gazebo reference="maggie">
  	</gazebo>
</robot>

