<?xml version="1.0" ?>
<!-- =================================================================================== -->
<!-- |    This document was autogenerated by xacro from maggie.xacro                   | -->
<!-- |    EDITING THIS FILE BY HAND IS NOT RECOMMENDED                                 | -->
<!-- =================================================================================== -->
<!-- XML namespaces -->
<robot name="pi_robot" xmlns:body="http://playerstage.sourceforge.net/gazebo/xmlschema/#body" xmlns:controller="http://playerstage.sourceforge.net/gazebo/xmlschema/#controller" xmlns:geom="http://playerstage.sourceforge.net/gazebo/xmlschema/#geom" xmlns:interface="http://playerstage.sourceforge.net/gazebo/xmlschema/#interface" xmlns:joint="http://playerstage.sourceforge.net/gazebo/xmlschema/#slider" xmlns:sensor="http://playerstage.sourceforge.net/gazebo/xmlschema/#sensor" xmlns:xacro="http://ros.org/wiki/xacro">
  <!--
	<include filename="$(find pi_robot_description)/urdf/sensors/hokuyo_laser_gazebo.xacro" />
	-->
  <material name="Blue">
    <color rgba="0.0 0.0 0.8 1.0"/>
  </material>
  <material name="Green">
    <color rgba="0.0 0.8 0.0 1.0"/>
  </material>
  <material name="Grey">
    <color rgba="0.7 0.7 0.7 1.0"/>
  </material>
  <material name="Grey2">
    <color rgba="0.9 0.9 0.9 1.0"/>
  </material>
  <material name="Red">
    <color rgba="0.8 0.0 0.0 1.0"/>
  </material>
  <material name="White">
    <color rgba="1.0 1.0 1.0 1.0"/>
  </material>
  <material name="Black">
    <color rgba="0.1 0.1 0.1 1.0"/>
  </material>
  <material name="LightGrey">
    <color rgba="0.6 0.6 0.6 1.0"/>
  </material>
  <material name="Caster">
    <texture filename="package://pr2_description/materials/textures/pr2_caster_texture.png"/>
  </material>
  <material name="Wheel_l">
    <texture filename="package://pr2_description/materials/textures/pr2_wheel_left.png"/>
  </material>
  <material name="Wheel_r">
    <texture filename="package://pr2_description/materials/textures/pr2_wheel_right.png"/>
  </material>
  <material name="RollLinks">
    <texture filename="package://pr2_description/materials/textures/pr2_wheel_left.png"/>
  </material>
  <!-- ============================   Body   ============================ -->
  <!--
 	<link name="world" />
 	-->
  <link name="base_link">
    <visual>
      <origin rpy="0 0 0" xyz="0 0 0"/>
      <geometry>
        <box size="0.36 0.52 0.02"/>
      </geometry>
      <material name="white">
        <color rgba="1.0 1.0 1.0 1.0"/>
      </material>
    </visual>
    <collision>
      <origin rpy="0 0 0" xyz="0 0 0"/>
      <geometry>
        <box size="0.36 0.52 0.02"/>
      </geometry>
    </collision>
    <xacro:default_inertial mass="0.5"/>
  </link>
  <gazebo reference="base_link">
    <material>Gazebo/WhiteEmissive</material>
    <selfCollide>false</selfCollide>
    <turnGravityOff>true</turnGravityOff>
  </gazebo>
  <link name="torso_link">
    <visual>
      <origin rpy="0 0 0" xyz="0 0 0"/>
      <geometry>
        <box size="0.005 0.4 0.75"/>
      </geometry>
      <material name="grey1">
        <color rgba="0.41 0.41 0.41 1.0"/>
      </material>
    </visual>
    <collision>
      <origin rpy="0 0 0" xyz="0 0 0"/>
      <geometry>
        <box size="0.005 0.4 0.75"/>
      </geometry>
    </collision>
    <xacro:default_inertial mass="0.5"/>
  </link>
  <gazebo reference="torso_link">
    <material>Gazebo/WhiteEmissive</material>
    <selfCollide>false</selfCollide>
    <turnGravityOff>true</turnGravityOff>
  </gazebo>
  <link name="shoulder_pan_support_link">
    <visual>
      <origin rpy="0 0 0" xyz="0 0 0"/>
      <geometry>
        <box size="0.06 0.04 0.005"/>
      </geometry>
      <material name="blue1">
        <color rgba="0 0 .8 1"/>
      </material>
    </visual>
    <collision>
      <origin rpy="0 0 0" xyz="0 0 0"/>
      <geometry>
        <box size="0.06 0.04 0.005"/>
      </geometry>
    </collision>
    <xacro:default_inertial mass="0.5"/>
  </link>
  <gazebo reference="shoulder_pan_support_link">
    <material>Gazebo/WhiteEmissive</material>
    <selfCollide>false</selfCollide>
    <turnGravityOff>true</turnGravityOff>
  </gazebo>
  <link name="shoulder_pan_link">
    <visual>
      <origin rpy="0 0 0" xyz="0 0 0"/>
      <geometry>
        <cylinder length="0.2" radius="0.05"/>
      </geometry>
      <material name="green1">
        <color rgba="0 1 0 0.5"/>
      </material>
    </visual>
    <collision>
      <origin rpy="0 0 0" xyz="0 0 0"/>
      <geometry>
        <cylinder length="0.2" radius="0.05"/>
      </geometry>
    </collision>
    <xacro:default_inertial mass="0.5"/>
  </link>
  <gazebo reference="shoulder_pan_link">
    <material>Gazebo/WhiteEmissive</material>
    <selfCollide>false</selfCollide>
    <turnGravityOff>true</turnGravityOff>
  </gazebo>
  <link name="shoulder_tilt_support_link">
    <visual>
      <origin rpy="0 0 0" xyz="0 0 0"/>
      <geometry>
        <box size="0.035 0.003 0.04"/>
      </geometry>
      <material name="blue1">
        <color rgba="0 0 .8 1"/>
      </material>
    </visual>
    <collision>
      <origin rpy="0 0 0" xyz="0 0 0"/>
      <geometry>
        <box size="0.035 0.003 0.04"/>
      </geometry>
    </collision>
    <xacro:default_inertial mass="0.5"/>
  </link>
  <gazebo reference="shoulder_tilt_support_link">
    <material>Gazebo/WhiteEmissive</material>
    <selfCollide>false</selfCollide>
    <turnGravityOff>true</turnGravityOff>
  </gazebo>
  <link name="shoulder_tilt_link">
    <visual>
      <origin rpy="0 0 0" xyz="0 0 -0.015"/>
      <geometry>
        <box size="0.01 0.003 0.03"/>
      </geometry>
      <material name="red1">
        <color rgba="1 0 0 0.5"/>
      </material>
    </visual>
    <collision>
      <origin rpy="0 0 0" xyz="0 0 -0.015"/>
      <geometry>
        <box size="0.01 0.003 0.03"/>
      </geometry>
    </collision>
    <xacro:default_inertial mass="0.5"/>
  </link>
  <gazebo reference="shoulder_tilt_link">
    <material>Gazebo/WhiteEmissive</material>
    <selfCollide>false</selfCollide>
    <turnGravityOff>true</turnGravityOff>
  </gazebo>
  <link name="upper_arm_link">
    <visual>
      <origin rpy="0 1.57 0" xyz="0.135 0 0"/>
      <geometry>
        <cylinder length="0.27" radius="0.025"/>
      </geometry>
      <material name="red1">
        <color rgba="1 0 0 0.5"/>
      </material>
    </visual>
    <collision>
      <origin rpy="0 1.57 0" xyz="0.135 0 0"/>
      <geometry>
        <cylinder length="0.27" radius="0.025"/>
      </geometry>
    </collision>
    <xacro:default_inertial mass="0.5"/>
  </link>
  <gazebo reference="upper_arm_link">
    <material>Gazebo/WhiteEmissive</material>
    <selfCollide>false</selfCollide>
    <turnGravityOff>true</turnGravityOff>
  </gazebo>
  <link name="elbow_tilt_link">
    <visual>
      <origin rpy="0 0 0" xyz="0.005 0 0"/>
      <geometry>
        <box size="0.01 0.003 0.03"/>
      </geometry>
      <material name="blue1">
        <color rgba="0 0 .8 1"/>
      </material>
    </visual>
    <collision>
      <origin rpy="0 0 0" xyz="0.005 0 0"/>
      <geometry>
        <box size="0.01 0.003 0.03"/>
      </geometry>
    </collision>
    <xacro:default_inertial mass="0.5"/>
  </link>
  <gazebo reference="elbow_tilt_link">
    <material>Gazebo/WhiteEmissive</material>
    <selfCollide>false</selfCollide>
    <turnGravityOff>true</turnGravityOff>
  </gazebo>
  <link name="forearm_link">
    <visual>
      <origin rpy="0 1.57 0" xyz="0.135 0 0"/>
      <geometry>
        <cylinder length="0.27" radius="0.025"/>
      </geometry>
      <material name="grey1">
        <color rgba="0.41 0.41 0.41 1.0"/>
      </material>
    </visual>
    <collision>
      <origin rpy="0 1.57 0" xyz="0.135 0 0"/>
      <geometry>
        <cylinder length="0.27" radius="0.025"/>
      </geometry>
    </collision>
    <xacro:default_inertial mass="0.5"/>
  </link>
  <gazebo reference="forearm_link">
    <material>Gazebo/WhiteEmissive</material>
    <selfCollide>false</selfCollide>
    <turnGravityOff>true</turnGravityOff>
  </gazebo>
  <link name="wrist_tilt_link">
    <visual>
      <origin rpy="0 0 0" xyz="0.015 0 0"/>
      <geometry>
        <box size="0.03 0.003 0.03"/>
      </geometry>
      <material name="blue1">
        <color rgba="0 0 .8 1"/>
      </material>
    </visual>
    <collision>
      <origin rpy="0 0 0" xyz="0.015 0 0"/>
      <geometry>
        <box size="0.03 0.003 0.03"/>
      </geometry>
    </collision>
    <xacro:default_inertial mass="0.5"/>
  </link>
  <gazebo reference="wrist_tilt_link">
    <material>Gazebo/WhiteEmissive</material>
    <selfCollide>false</selfCollide>
    <turnGravityOff>true</turnGravityOff>
  </gazebo>
  <joint name="r_gripper_palm_joint" type="fixed">
    <origin rpy="0 0 0" xyz="0 0 0"/>
    <parent link="wrist_tilt_link"/>
    <child link="r_gripper_palm_link"/>
  </joint>
  <link name="r_gripper_palm_link">
    <inertial>
      <mass value="0.58007"/>
      <origin rpy="0 0 0" xyz="0.06623 0.00053 -0.00119"/>
      <inertia ixx="0.00035223921" ixy="-0.00001580476" ixz="-0.00000091750" iyy="0.00067741312" iyz="-0.00000059554" izz="0.00086563316"/>
    </inertial>
    <visual>
      <origin rpy="0 0 0" xyz="0 0 0"/>
      <geometry>
        <mesh filename="package://pr2_description/meshes/gripper_v0/gripper_palm.dae"/>
      </geometry>
      <material name="Red"/>
    </visual>
    <collision>
      <origin rpy="0 0 0" xyz="0 0 0"/>
      <geometry>
        <mesh filename="package://pr2_description/meshes/gripper_v0/gripper_palm.stl"/>
      </geometry>
    </collision>
  </link>
  <joint name="r_gripper_led_joint" type="fixed">
    <!--  Need to check if we need a positive or negative Z term -->
    <origin xyz="0.0513 0.0 .0244"/>
    <parent link="r_gripper_palm_link"/>
    <child link="r_gripper_led_frame"/>
  </joint>
  <link name="r_gripper_led_frame"/>
  <joint name="r_gripper_motor_accelerometer_joint" type="fixed">
    <origin rpy="0 0 0" xyz="0 0 0"/>
    <parent link="r_gripper_palm_link"/>
    <child link="r_gripper_motor_accelerometer_link"/>
  </joint>
  <link name="r_gripper_motor_accelerometer_link">
    <inertial>
      <mass value="0.001"/>
      <origin rpy="0 0 0" xyz="0 0 0"/>
      <inertia ixx="0.001" ixy="0.0" ixz="0.0" iyy="0.001" iyz="0.0" izz="0.001"/>
    </inertial>
    <visual>
      <origin rpy="0 0 0" xyz="0 0 0"/>
      <geometry>
        <box size="0.001 0.001 0.001"/>
      </geometry>
    </visual>
    <collision>
      <origin rpy="0 0 0" xyz="0 0 0"/>
      <geometry>
        <box size="0.001 0.001 0.001"/>
      </geometry>
    </collision>
  </link>
  <joint name="r_gripper_tool_joint" type="fixed">
    <origin rpy="0 0 0" xyz="0.18 0 0"/>
    <parent link="r_gripper_palm_link"/>
    <child link="r_gripper_tool_frame"/>
  </joint>
  <link name="r_gripper_tool_frame"/>
  <link name="r_gripper_motor_slider_link">
    <inertial>
      <mass value="0.01"/>
      <origin rpy="0 0 0" xyz="0 0 0"/>
      <inertia ixx="0.001" ixy="0.0" ixz="0.0" iyy="0.001" iyz="0.0" izz="0.001"/>
    </inertial>
    <!-- for debugging only
      <visual>
        <origin xyz="0 0 0" rpy="1.5708 0 0" />
        <geometry>
          <cylinder length="0.002" radius="0.025"/>
        </geometry>
      </visual>
      <collision>
        <origin xyz="0 0 0" rpy="1.5708 0 0" />
        <geometry>
          <cylinder length="0.002" radius="0.025"/>
        </geometry>
      </collision>
      -->
  </link>
  <joint name="r_gripper_motor_slider_joint" type="prismatic">
    <origin rpy="0 0 0" xyz="0.16828 0 0"/>
    <axis xyz="1 0 0"/>
    <parent link="r_gripper_palm_link"/>
    <child link="r_gripper_motor_slider_link"/>
    <limit effort="1000.0" lower="-0.1" upper="0.1" velocity="0.2"/>
  </joint>
  <link name="r_gripper_motor_screw_link">
    <inertial>
      <mass value="0.01"/>
      <origin rpy="0 0 0" xyz="0 0 0"/>
      <inertia ixx="0.0001" ixy="0.0" ixz="0.0" iyy="0.0001" iyz="0.0" izz="0.0001"/>
    </inertial>
    <!-- for debugging only
      <visual>
        <origin xyz="0 0 0" rpy="0 0 0" />
        <geometry>
          <box size="0.05 0.001 0.05" />
        </geometry>
      </visual>
      <collision>
        <origin xyz="0 0 0" rpy="0 0 0" />
        <geometry>
          <box size="0.05 0.001 0.05" />
        </geometry>
      </collision>
      -->
  </link>
  <joint name="r_gripper_motor_screw_joint" type="continuous">
    <origin rpy="0 0 0" xyz="0.0 0 0"/>
    <axis xyz="0 1 0"/>
    <parent link="r_gripper_motor_slider_link"/>
    <child link="r_gripper_motor_screw_link"/>
    <dynamics damping="0.0001"/>
  </joint>
  <joint name="r_gripper_l_finger_joint" type="revolute">
    <axis xyz="0 0 1"/>
    <limit effort="1000.0" lower="0.0" upper="0.548" velocity="0.5"/>
    <dynamics damping="0.02"/>
    <origin rpy="0 0 0" xyz="0.07691 0.01 0"/>
    <parent link="r_gripper_palm_link"/>
    <child link="r_gripper_l_finger_link"/>
  </joint>
  <link name="r_gripper_l_finger_link">
    <inertial>
      <mass value="0.17126"/>
      <origin rpy="0 0 0" xyz="0.03598 0.01730 -0.00164"/>
      <inertia ixx="0.00007756198" ixy="0.00000149095" ixz="-0.00000983385" iyy="0.00019708305" iyz="-0.00000306125" izz="0.00018105446"/>
    </inertial>
    <visual>
      <origin rpy="0 0 0" xyz="0 0 0"/>
      <geometry>
        <mesh filename="package://pr2_description/meshes/gripper_v0/l_finger.dae"/>
      </geometry>
      <material name="Grey"/>
    </visual>
    <collision>
      <origin rpy="0 0 0" xyz="0 0 0"/>
      <geometry>
        <mesh filename="package://pr2_description/meshes/gripper_v0/l_finger.stl"/>
      </geometry>
    </collision>
  </link>
  <joint name="r_gripper_r_finger_joint" type="revolute">
    <axis xyz="0 0 -1"/>
    <origin rpy="0 0 0" xyz="0.07691 -0.01 0"/>
    <limit effort="1000.0" lower="0.0" upper="0.548" velocity="0.5"/>
    <dynamics damping="0.02"/>
    <mimic joint="r_gripper_l_finger_joint" multiplier="1" offset="0"/>
    <parent link="r_gripper_palm_link"/>
    <child link="r_gripper_r_finger_link"/>
  </joint>
  <link name="r_gripper_r_finger_link">
    <inertial>
      <mass value="0.17389"/>
      <origin rpy="0 0 0" xyz="0.03576 -0.01736 -0.00095"/>
      <inertia ixx="0.00007738410" ixy="-0.00000209309" ixz="-0.00000836228" iyy="0.00019847383" iyz="0.00000246110" izz="0.00018106988"/>
    </inertial>
    <visual>
      <origin rpy="3.14159265359 0 0" xyz="0 0 0"/>
      <geometry>
        <mesh filename="package://pr2_description/meshes/gripper_v0/l_finger.dae"/>
      </geometry>
      <material name="Grey"/>
    </visual>
    <collision>
      <origin rpy="3.14159265359 0 0" xyz="0 0 0"/>
      <geometry>
        <mesh filename="package://pr2_description/meshes/gripper_v0/l_finger.stl"/>
      </geometry>
    </collision>
  </link>
  <joint name="r_gripper_l_finger_tip_joint" type="revolute">
    <axis xyz="0 0 -1"/>
    <origin rpy="0 0 0" xyz="0.09137 0.00495 0"/>
    <limit effort="1000.0" lower="0.0" upper="0.548" velocity="0.5"/>
    <dynamics damping="0.001"/>
    <mimic joint="r_gripper_l_finger_joint" multiplier="1" offset="0"/>
    <parent link="r_gripper_l_finger_link"/>
    <child link="r_gripper_l_finger_tip_link"/>
  </joint>
  <link name="r_gripper_l_finger_tip_link">
    <inertial>
      <mass value="0.04419"/>
      <origin rpy="0 0 0" xyz="0.00423 0.00284 0.0"/>
      <inertia ixx="0.00000837047" ixy="0.00000583632" ixz="0.0" iyy="0.00000987067" iyz="0.0" izz="0.00001541768"/>
    </inertial>
    <visual>
      <origin rpy="0 0 0" xyz="0 0 0"/>
      <geometry>
        <mesh filename="package://pr2_description/meshes/gripper_v0/l_finger_tip.dae"/>
      </geometry>
      <material name="Green"/>
    </visual>
    <collision>
      <origin rpy="0 0 0" xyz="0 0 0"/>
      <geometry>
        <mesh filename="package://pr2_description/meshes/gripper_v0/l_finger_tip.stl"/>
      </geometry>
    </collision>
  </link>
  <joint name="r_gripper_r_finger_tip_joint" type="revolute">
    <axis xyz="0 0 1"/>
    <origin rpy="0 0 0" xyz="0.09137 -0.00495 0"/>
    <limit effort="1000.0" lower="0.0" upper="0.548" velocity="0.5"/>
    <dynamics damping="0.001"/>
    <mimic joint="r_gripper_l_finger_joint" multiplier="1" offset="0"/>
    <parent link="r_gripper_r_finger_link"/>
    <child link="r_gripper_r_finger_tip_link"/>
  </joint>
  <link name="r_gripper_r_finger_tip_link">
    <inertial>
      <mass value="0.04419"/>
      <origin rpy="0 0 0" xyz="0.00423 -0.00284 0.0"/>
      <inertia ixx="0.00000837047" ixy="-0.00000583632" ixz="0.0" iyy="0.00000987067" iyz="0.0" izz="0.00001541768"/>
    </inertial>
    <visual>
      <origin rpy="3.14159265359 0 0" xyz="0 0 0"/>
      <geometry>
        <mesh filename="package://pr2_description/meshes/gripper_v0/l_finger_tip.dae"/>
      </geometry>
      <material name="Green"/>
    </visual>
    <collision>
      <origin rpy="3.14159265359 0 0" xyz="0 0 0"/>
      <geometry>
        <mesh filename="package://pr2_description/meshes/gripper_v0/l_finger_tip.stl"/>
      </geometry>
    </collision>
  </link>
  <gazebo reference="r_gripper_l_finger_link">
    <turnGravityOff>true</turnGravityOff>
    <mu1 value="500.0"/>
    <mu2 value="500.0"/>
    <kp value="1000000.0"/>
    <kd value="1.0"/>
    <!-- for "${prefix}_l_finger_joint"-->
  </gazebo>
  <gazebo reference="r_gripper_l_finger_joint">
    <stopKd value="1.0"/>
    <stopKp value="10000000.0"/>
    <fudgeFactor value="1.0"/>
    <provideFeedback value="true"/>
  </gazebo>
  <gazebo reference="r_gripper_r_finger_link">
    <turnGravityOff>true</turnGravityOff>
    <mu1 value="500.0"/>
    <mu2 value="500.0"/>
    <kp value="1000000.0"/>
    <kd value="1.0"/>
  </gazebo>
  <gazebo reference="r_gripper_r_finger_joint">
    <stopKd value="1.0"/>
    <stopKp value="10000000.0"/>
    <fudgeFactor value="1.0"/>
    <provideFeedback value="true"/>
  </gazebo>
  <gazebo reference="r_gripper_l_finger_tip_link">
    <turnGravityOff>true</turnGravityOff>
    <selfCollide>false</selfCollide>
    <sensor:contact name="r_gripper_l_finger_tip_contact_sensor">
      <geom>r_gripper_l_finger_tip_link_geom</geom>
      <updateRate>100.0</updateRate>
      <controller:gazebo_ros_bumper name="r_gripper_l_finger_tip_gazebo_ros_bumper_controller" plugin="libgazebo_ros_bumper.so">
        <alwaysOn>true</alwaysOn>
        <frameName>r_gripper_l_finger_tip_link</frameName>
        <updateRate>100.0</updateRate>
        <bumperTopicName>r_gripper_l_finger_tip_bumper</bumperTopicName>
        <interface:bumper name="r_gripper_l_finger_tip_gazebo_ros_bumper_iface"/>
      </controller:gazebo_ros_bumper>
    </sensor:contact>
    <mu1 value="500.0"/>
    <mu2 value="500.0"/>
    <kp value="10000000.0"/>
    <kd value="1.0"/>
  </gazebo>
  <gazebo reference="r_gripper_l_finger_tip_joint">
    <stopKd value="1.0"/>
    <stopKp value="10000000.0"/>
    <fudgeFactor value="1.0"/>
    <provideFeedback value="true"/>
  </gazebo>
  <gazebo reference="r_gripper_r_finger_tip_link">
    <turnGravityOff>true</turnGravityOff>
    <selfCollide>false</selfCollide>
    <sensor:contact name="r_gripper_r_finger_tip_contact_sensor">
      <geom>r_gripper_r_finger_tip_link_geom</geom>
      <updateRate>100.0</updateRate>
      <controller:gazebo_ros_bumper name="r_gripper_r_finger_tip_gazebo_ros_bumper_controller" plugin="libgazebo_ros_bumper.so">
        <alwaysOn>true</alwaysOn>
        <frameName>r_gripper_r_finger_tip_link</frameName>
        <updateRate>100.0</updateRate>
        <bumperTopicName>r_gripper_r_finger_tip_bumper</bumperTopicName>
        <interface:bumper name="r_gripper_r_finger_tip_gazebo_ros_bumper_iface"/>
      </controller:gazebo_ros_bumper>
    </sensor:contact>
    <mu1 value="500.0"/>
    <mu2 value="500.0"/>
    <kp value="10000000.0"/>
    <kd value="1.0"/>
  </gazebo>
  <gazebo>
    <controller:gazebo_ros_p3d name="p3d_r_gripper_l_finger_controller" plugin="libgazebo_ros_p3d.so">
      <alwaysOn>true</alwaysOn>
      <updateRate>100.0</updateRate>
      <bodyName>r_gripper_l_finger_link</bodyName>
      <topicName>r_gripper_l_finger_pose_ground_truth</topicName>
      <gaussianNoise>0.0</gaussianNoise>
      <frameName>base_link</frameName>
      <interface:position name="p3d_r_gripper_l_finger_position_iface"/>
    </controller:gazebo_ros_p3d>
    <controller:gazebo_ros_f3d name="f3d_r_gripper_l_finger_controller" plugin="libgazebo_ros_f3d.so">
      <alwaysOn>true</alwaysOn>
      <updateRate>100.0</updateRate>
      <bodyName>r_gripper_l_finger_link</bodyName>
      <topicName>r_gripper_l_finger_force_ground_truth</topicName>
      <frameName>r_gripper_l_finger_link</frameName>
      <interface:position name="f3d_r_gripper_l_finger_force_iface"/>
    </controller:gazebo_ros_f3d>
  </gazebo>
  <gazebo reference="r_gripper_r_finger_tip_joint">
    <stopKd value="1.0"/>
    <stopKp value="10000000.0"/>
    <fudgeFactor value="1.0"/>
    <provideFeedback value="true"/>
  </gazebo>
  <gazebo>
    <body:box name="r_gripper_l_parallel_link">
      <massMatrix>true</massMatrix>
      <mass>0.17126</mass>
      <ixx>7.7562e-05</ixx>
      <ixy>1.49095e-06</ixy>
      <ixz>-9.83385e-06</ixz>
      <iyy>0.000197083</iyy>
      <iyz>-3.06125e-06</iyz>
      <izz>0.000181054</izz>
      <cx>0.03598</cx>
      <cy>0.0173</cy>
      <cz>-0.00164</cz>
      <xyz>0.82991 -0.157 0.790675</xyz>
      <rpy>0 -0 0</rpy>
      <turnGravityOff>true</turnGravityOff>
      <selfCollide>false</selfCollide>
    </body:box>
    <body:box name="r_gripper_r_parallel_link">
      <massMatrix>true</massMatrix>
      <mass>0.17389</mass>
      <ixx>7.73841e-05</ixx>
      <ixy>-2.09309e-06</ixy>
      <ixz>-8.36228e-06</ixz>
      <iyy>0.000198474</iyy>
      <iyz>2.4611e-06</iyz>
      <izz>0.00018107</izz>
      <cx>0.03576</cx>
      <cy>-0.01736</cy>
      <cz>-0.00095</cz>
      <xyz>0.82991 -0.219 0.790675</xyz>
      <rpy>0 -0 0</rpy>
      <turnGravityOff>true</turnGravityOff>
      <selfCollide>false</selfCollide>
    </body:box>
  </gazebo>
  <gazebo>
    <joint:screw name="r_gripper_r_screw_screw_joint">
      <body1>r_gripper_motor_screw_link</body1>
      <body2>r_gripper_r_finger_tip_link</body2>
      <anchor>r_gripper_motor_screw_link</anchor>
      <anchorOffset>0 0 0</anchorOffset>
      <axis>0 1 0</axis>
      <threadPitch>-3141.6</threadPitch>
    </joint:screw>
    <joint:screw name="r_gripper_l_screw_screw_joint">
      <body1>r_gripper_motor_screw_link</body1>
      <body2>r_gripper_l_finger_tip_link</body2>
      <anchor>r_gripper_motor_screw_link</anchor>
      <anchorOffset>0 0 0</anchorOffset>
      <axis>0 1 0</axis>
      <threadPitch>3141.6</threadPitch>
    </joint:screw>
  </gazebo>
  <gazebo>
    <joint:hinge name="r_gripper_r_parallel_root_joint">
      <body1>r_gripper_r_parallel_link</body1>
      <body2>r_gripper_palm_link</body2>
      <anchor>r_gripper_palm_link</anchor>
      <axis>0 0 -1</axis>
      <damping>0.2</damping>
      <anchorOffset>0.05891 -0.031 0</anchorOffset>
    </joint:hinge>
    <joint:hinge name="r_gripper_l_parallel_root_joint">
      <body1>r_gripper_l_parallel_link</body1>
      <body2>r_gripper_palm_link</body2>
      <anchor>r_gripper_palm_link</anchor>
      <axis>0 0 1</axis>
      <damping>0.2</damping>
      <anchorOffset>0.05891 0.031 0</anchorOffset>
    </joint:hinge>
    <joint:hinge name="r_gripper_r_parallel_tip_joint">
      <body1>r_gripper_r_parallel_link</body1>
      <body2>r_gripper_r_finger_tip_link</body2>
      <anchor>r_gripper_r_finger_tip_link</anchor>
      <axis>0 0 1</axis>
      <anchorOffset>-0.018 -0.021 0</anchorOffset>
    </joint:hinge>
    <joint:hinge name="r_gripper_l_parallel_tip_joint">
      <body1>r_gripper_l_parallel_link</body1>
      <body2>r_gripper_l_finger_tip_link</body2>
      <anchor>r_gripper_l_finger_tip_link</anchor>
      <axis>0 0 1</axis>
      <anchorOffset>-0.018 0.021 0</anchorOffset>
    </joint:hinge>
    <joint:slider name="r_gripper_joint">
      <body1>r_gripper_l_finger_tip_link</body1>
      <body2>r_gripper_r_finger_tip_link</body2>
      <anchor>r_gripper_l_finger_tip_link</anchor>
      <axis>0 1 0</axis>
    </joint:slider>
  </gazebo>
  <gazebo reference="r_gripper_motor_slider_link">
    <turnGravityOff>true</turnGravityOff>
    <material value="PR2/Red"/>
  </gazebo>
  <gazebo reference="r_gripper_motor_screw_link">
    <turnGravityOff>true</turnGravityOff>
    <material value="PR2/Red"/>
  </gazebo>
  <gazebo reference="r_gripper_l_parallel_link">
    <turnGravityOff>true</turnGravityOff>
    <material value="PR2/Red"/>
  </gazebo>
  <gazebo reference="r_gripper_r_parallel_link">
    <turnGravityOff>true</turnGravityOff>
    <material value="PR2/Red"/>
  </gazebo>
  <joint name="r_gripper_joint" type="prismatic">
    <parent link="r_gripper_r_finger_tip_link"/>
    <child link="r_gripper_l_finger_tip_frame"/>
    <axis xyz="0 1 0"/>
    <dynamics damping="10.0"/>
    <limit effort="1000.0" lower="0.0" upper="0.09" velocity="0.2"/>
    <safety_controller k_position="20.0" k_velocity="5000.0" soft_lower_limit="-0.01" soft_upper_limit="0.088"/>
  </joint>
  <link name="r_gripper_l_finger_tip_frame"/>
  <gazebo reference="r_gripper_palm_link">
    <turnGravityOff>true</turnGravityOff>
  </gazebo>
  <gazebo>
    <controller:gazebo_ros_p3d name="p3d_r_gripper_palm_controller" plugin="libgazebo_ros_p3d.so">
      <alwaysOn>true</alwaysOn>
      <updateRate>100.0</updateRate>
      <bodyName>r_gripper_palm_link</bodyName>
      <topicName>r_gripper_palm_pose_ground_truth</topicName>
      <xyzOffsets>0 0 0</xyzOffsets>
      <rpyOffsets>0 0 0</rpyOffsets>
      <gaussianNoise>0.0</gaussianNoise>
      <frameName>map</frameName>
      <interface:position name="p3d_r_gripper_palm_position_iface"/>
    </controller:gazebo_ros_p3d>
    <!-- a formal implementation of grasp hack in gazebo with fixed joint -->
    <gripper name="r_grasp_hack">
      <grasp_check attach_steps="20" detach_steps="40" min_contact_count="2"/>
      <gripper_link>r_gripper_r_finger_tip_link</gripper_link>
      <gripper_link>r_gripper_l_finger_tip_link</gripper_link>
      <palm_link>r_gripper_palm_link</palm_link>
    </gripper>
  </gazebo>
  <transmission name="r_gripper_trans" type="pr2_mechanism_model/PR2GripperTransmission">
    <actuator name="r_gripper_motor"/>
    <gap_joint L0="0.0375528" a="0.0683698" b="0.0433849" gear_ratio="40.095" h="0.0" mechanical_reduction="1.0" name="r_gripper_joint" phi0="0.518518122146" r="0.0915" screw_reduction="0.004" t0="-0.0001914" theta0="0.0628824676201"/>
    <!-- if a gazebo joint exists as [l|r]_gripper_joint, use this tag to have
           gripper transmission apply torque directly to prismatic joint
           this should be the default behavior in diamondback, deprecating this flag -->
    <use_simulated_gripper_joint/>
    <!-- set passive joint angles so things look nice in rviz -->
    <passive_joint name="r_gripper_l_finger_joint"/>
    <passive_joint name="r_gripper_r_finger_joint"/>
    <passive_joint name="r_gripper_r_finger_tip_joint"/>
    <passive_joint name="r_gripper_l_finger_tip_joint"/>
    <!-- screw joint to capture gripper "dynamics" -->
    <simulated_actuated_joint name="r_gripper_motor_screw_joint" passive_actuated_joint="r_gripper_motor_slider_joint" simulated_reduction="3141.6"/>
  </transmission>
  <!-- head links -->
  <link name="lower_neck_link">
    <visual>
      <origin rpy="0 0 0" xyz="0 0 0"/>
      <geometry>
        <cylinder length="0.16" radius="0.025"/>
      </geometry>
      <material name="grey1">
        <color rgba="0.41 0.41 0.41 1.0"/>
      </material>
    </visual>
    <collision>
      <origin rpy="0 0 0" xyz="0 0 0"/>
      <geometry>
        <cylinder length="0.16" radius="0.025"/>
      </geometry>
    </collision>
    <xacro:default_inertial mass="0.05"/>
  </link>
  <gazebo reference="lower_neck_link">
    <material>Gazebo/WhiteEmissive</material>
    <selfCollide>false</selfCollide>
    <turnGravityOff>true</turnGravityOff>
  </gazebo>
  <link name="upper_neck_link">
    <visual>
      <origin rpy="0 0 0" xyz="0 0 0.01"/>
      <geometry>
        <box size="0.028 0.048 0.037"/>
      </geometry>
      <material name="bracket_color">
        <color rgba="0.9 0.9 0.9 1.0"/>
      </material>
    </visual>
    <collision>
      <origin rpy="0 0 0" xyz="0 0 0.01"/>
      <geometry>
        <box size="0.028 0.048 0.037"/>
      </geometry>
    </collision>
    <xacro:default_inertial mass="0.05"/>
  </link>
  <gazebo reference="upper_neck_link">
    <material>Gazebo/WhiteEmissive</material>
    <selfCollide>false</selfCollide>
    <turnGravityOff>true</turnGravityOff>
  </gazebo>
  <link name="head_pan_link">
    <visual>
      <origin rpy="0 0 0" xyz="0 0 0"/>
      <geometry>
        <box size="0.05 0.035 0.04"/>
      </geometry>
      <material name="ax12_color">
        <color rgba="0.1 0.1 0.1 1.0"/>
      </material>
    </visual>
    <collision>
      <origin rpy="0 0 0" xyz="0 0 0"/>
      <geometry>
        <box size="0.05 0.035 0.04"/>
      </geometry>
    </collision>
    <xacro:default_inertial mass="0.055"/>
  </link>
  <gazebo reference="head_pan_link">
    <material>Gazebo/FlatBlack</material>
    <selfCollide>false</selfCollide>
    <turnGravityOff>true</turnGravityOff>
  </gazebo>
  <link name="head_tilt_link">
    <visual>
      <origin rpy="0 0 0" xyz="0 0 0"/>
      <geometry>
        <box size="0.03 0.038 0.057"/>
      </geometry>
      <material name="ax12_color">
        <color rgba="0.1 0.1 0.1 1.0"/>
      </material>
    </visual>
    <collision>
      <origin rpy="0 0 0" xyz="0 0 0"/>
      <geometry>
        <box size="0.03 0.038 0.057"/>
      </geometry>
    </collision>
    <xacro:default_inertial mass="0.055"/>
  </link>
  <gazebo reference="head_tilt_link">
    <material>Gazebo/FlatBlack</material>
    <selfCollide>false</selfCollide>
    <turnGravityOff>true</turnGravityOff>
  </gazebo>
  <link name="head_base_link">
    <visual>
      <origin rpy="0 0 0" xyz="0 0 00"/>
      <geometry>
        <box size="0.06 0.08 0.022"/>
      </geometry>
      <material name="black">
        <color rgba="0.1 0.1 0.1 1.0"/>
      </material>
    </visual>
    <collision>
      <origin rpy="0 0 0" xyz="0 0 00"/>
      <geometry>
        <box size="0.06 0.08 0.022"/>
      </geometry>
    </collision>
    <xacro:default_inertial mass="0.1"/>
  </link>
  <gazebo reference="head_base_link">
    <material>Gazebo/FlatBlack</material>
    <selfCollide>false</selfCollide>
    <turnGravityOff>true</turnGravityOff>
  </gazebo>
  <link name="head_post_link">
    <visual>
      <origin rpy="0 0 0" xyz="0 0 00"/>
      <geometry>
        <cylinder length="0.012" radius="0.005"/>
      </geometry>
      <material name="grey1">
        <color rgba="0.41 0.41 0.41 1.0"/>
      </material>
    </visual>
    <collision>
      <origin rpy="0 0 0" xyz="0 0 00"/>
      <geometry>
        <cylinder length="0.012" radius="0.005"/>
      </geometry>
    </collision>
    <xacro:default_inertial mass="0.1"/>
  </link>
  <gazebo reference="head_post_link">
    <material>Gazebo/WhiteEmissive</material>
    <selfCollide>false</selfCollide>
    <turnGravityOff>true</turnGravityOff>
  </gazebo>
  <link name="head_link">
    <visual>
      <origin rpy="0 0 0" xyz="0 0 00"/>
      <geometry>
        <box size="0.06 0.26 0.035"/>
      </geometry>
      <material name="black">
        <color rgba="0.1 0.1 0.1 1.0"/>
      </material>
    </visual>
    <collision>
      <origin rpy="0 0 0" xyz="0 0 00"/>
      <geometry>
        <box size="0.06 0.26 0.035"/>
      </geometry>
    </collision>
    <xacro:default_inertial mass="0.8"/>
  </link>
  <gazebo reference="head_link">
    <material>Gazebo/FlatBlack</material>
    <selfCollide>false</selfCollide>
    <turnGravityOff>true</turnGravityOff>
  </gazebo>
  <link name="left_eye_link">
    <visual>
      <origin rpy="0 0 0" xyz="0 0 00"/>
      <geometry>
        <cylinder length="0.01" radius="0.01"/>
      </geometry>
      <material name="grey1">
        <color rgba="0.41 0.41 0.41 1.0"/>
      </material>
    </visual>
    <collision>
      <origin rpy="0 0 0" xyz="0 0 00"/>
      <geometry>
        <cylinder length="0.01" radius="0.01"/>
      </geometry>
    </collision>
    <xacro:default_inertial mass="0.001"/>
  </link>
  <gazebo reference="left_eye_link">
    <material>Gazebo/WhiteEmissive</material>
    <selfCollide>false</selfCollide>
    <turnGravityOff>true</turnGravityOff>
  </gazebo>
  <link name="right_eye_link">
    <visual>
      <origin rpy="0 0 0" xyz="0 0 00"/>
      <geometry>
        <cylinder length="0.01" radius="0.01"/>
      </geometry>
      <material name="grey1">
        <color rgba="0.41 0.41 0.41 1.0"/>
      </material>
    </visual>
    <collision>
      <origin rpy="0 0 0" xyz="0 0 00"/>
      <geometry>
        <cylinder length="0.01" radius="0.01"/>
      </geometry>
    </collision>
    <xacro:default_inertial mass="0.001"/>
  </link>
  <gazebo reference="right_eye_link">
    <material>Gazebo/WhiteEmissive</material>
    <selfCollide>false</selfCollide>
    <turnGravityOff>true</turnGravityOff>
  </gazebo>
  <!-- ============================   Arms   ============================ -->
  <!-- =================== Joint Definitions ==================== -->
  <!-- head joints -->
  <joint name="lower_neck_joint" type="fixed">
    <parent link="torso_link"/>
    <child link="lower_neck_link"/>
    <origin rpy="0 0 0" xyz="-0.0275 0 0.455"/>
  </joint>
  <joint name="head_pan_servo_joint" type="fixed">
    <parent link="lower_neck_link"/>
    <child link="head_pan_link"/>
    <origin rpy="0 0 0" xyz="0.02 0 0.1"/>
  </joint>
  <joint name="head_pan_joint" type="revolute">
    <parent link="head_pan_link"/>
    <child link="head_tilt_link"/>
    <origin rpy="0 0 0" xyz="0.01 0 0.048"/>
    <axis xyz="0 0 1"/>
    <limit effort="10" lower="-3.1416" upper="3.1416" velocity="3"/>
    <dynamics damping="0.0"/>
  </joint>
  <joint name="head_tilt_joint" type="revolute">
    <parent link="head_tilt_link"/>
    <child link="upper_neck_link"/>
    <origin rpy="0 0 0" xyz="0 0 0.013"/>
    <axis xyz="0 1 0"/>
    <limit effort="10" lower="-1.57" upper="1.57" velocity="3"/>
    <dynamics damping="0.0"/>
  </joint>
  <joint name="upper_neck_joint" type="fixed">
    <parent link="upper_neck_link"/>
    <child link="head_base_link"/>
    <origin rpy="0 0 0" xyz="0 0 0.040"/>
  </joint>
  <joint name="head_base_joint" type="fixed">
    <parent link="head_base_link"/>
    <child link="head_post_link"/>
    <origin rpy="0 0 0" xyz="0 0 0.016"/>
  </joint>
  <joint name="head_joint" type="fixed">
    <parent link="head_post_link"/>
    <child link="head_link"/>
    <origin rpy="0 0 0" xyz="0 0 0.0235"/>
  </joint>
  <joint name="left_eye_joint" type="fixed">
    <parent link="head_link"/>
    <child link="left_eye_link"/>
    <origin rpy="0 1.57 0" xyz="0.026 0.05 0"/>
  </joint>
  <joint name="right_eye_joint" type="fixed">
    <parent link="head_link"/>
    <child link="right_eye_link"/>
    <origin rpy="0 1.57 0" xyz="0.026 -0.05 0"/>
  </joint>
  <!-- arm joints -->
  <joint name="wrist_tilt_joint" type="revolute">
    <parent link="forearm_link"/>
    <child link="wrist_tilt_link"/>
    <axis xyz="0 1 0"/>
    <origin rpy="0 0 0" xyz="0.255 0 0"/>
    <limit effort="1.0" lower="-1.0" upper="1.0" velocity="1.0"/>
  </joint>
  <joint name="forearm_roll_joint" type="revolute">
    <parent link="elbow_tilt_link"/>
    <child link="forearm_link"/>
    <axis xyz="0.135 0 0"/>
    <origin rpy="0 0 0" xyz="0 0 0"/>
    <limit effort="1.0" lower="-1.0" upper="1.0" velocity="1.0"/>
  </joint>
  <joint name="elbow_tilt_joint" type="revolute">
    <parent link="upper_arm_link"/>
    <child link="elbow_tilt_link"/>
    <axis xyz="0 1 0"/>
    <origin rpy="0 0 0" xyz="0.27 0 0"/>
    <limit effort="1.0" lower="-1.0" upper="1.0" velocity="1.0"/>
  </joint>
  <joint name="upper_arm_roll_joint" type="revolute">
    <parent link="shoulder_tilt_link"/>
    <child link="upper_arm_link"/>
    <axis xyz="0.135 0 0"/>
    <origin rpy="0 0 0" xyz="0 0 0"/>
    <limit effort="1.0" lower="-1.0" upper="1.0" velocity="1.0"/>
  </joint>
  <joint name="shoulder_tilt_joint" type="revolute">
    <parent link="shoulder_tilt_support_link"/>
    <child link="shoulder_tilt_link"/>
    <axis xyz="0 1 0"/>
    <origin rpy="0 0 0" xyz="0 0 -0.015"/>
    <limit effort="1.0" lower="-1.0" upper="1.0" velocity="1.0"/>
  </joint>
  <joint name="shoulder_tilt_support_joint" type="fixed">
    <parent link="shoulder_pan_link"/>
    <child link="shoulder_tilt_support_link"/>
    <origin rpy="0 0 0" xyz="0.0175 0.0 0"/>
  </joint>
  <joint name="shoulder_pan_joint" type="revolute">
    <parent link="shoulder_pan_support_link"/>
    <child link="shoulder_pan_link"/>
    <axis xyz="0.0 0 1"/>
    <origin rpy="0 0 0" xyz="0.03 0 0"/>
    <limit effort="1.0" lower="-1.0" upper="1.0" velocity="1.0"/>
  </joint>
  <joint name="shoulder_pan_support_joint" type="fixed">
    <parent link="torso_link"/>
    <child link="shoulder_pan_support_link"/>
    <origin rpy="0 0 0" xyz="0.0325 -0.14 0.173"/>
  </joint>
  <joint name="torso_joint" type="fixed">
    <parent link="base_link"/>
    <child link="torso_link"/>
    <origin rpy="0 0 0" xyz="0 0 0.375"/>
  </joint>
  <gazebo reference="maggie">
  	</gazebo>
</robot>
