<?xml version="1.0" ?>
<!-- =================================================================================== -->
<!-- |    This document was autogenerated by xacro from pi_robot.xacro                 | -->
<!-- |    EDITING THIS FILE BY HAND IS NOT RECOMMENDED                                 | -->
<!-- =================================================================================== -->
<!-- XML namespaces -->
<robot name="pi_robot" xmlns:controller="http://playerstage.sourceforge.net/gazebo/xmlschema/#controller" xmlns:interface="http://playerstage.sourceforge.net/gazebo/xmlschema/#interface" xmlns:sensor="http://playerstage.sourceforge.net/gazebo/xmlschema/#sensor" xmlns:xacro="http://ros.org/wiki/xacro">
  <!--
	<include filename="$(find pi_robot_description)/urdf/sensors/hokuyo_laser_gazebo.xacro" />
	-->
  <!-- ============================   Body   ============================ -->
  <!--
 	<link name="world" />
 	-->
  <link name="base_link">
    <visual>
      <origin rpy="0 0 0" xyz="0 0 0.05"/>
      <geometry>
        <box size="0.32 0.26 0.053"/>
      </geometry>
      <material name="grey2">
        <color rgba="0.6 0.6 0.6 1.0"/>
      </material>
    </visual>
    <collision>
      <origin rpy="0 0 0" xyz="0 0 0.05"/>
      <geometry>
        <box size="0.32 0.26 0.053"/>
      </geometry>
    </collision>
    <inertial>
      <mass value="0.5"/>
      <inertia ixx="0.001" ixy="0.0" ixz="0.0" iyy="0.001" iyz="0.0" izz="0.001"/>
    </inertial>
  </link>
  <gazebo reference="base_link">
    <material>Gazebo/Grey</material>
    <selfCollide>false</selfCollide>
    <turnGravityOff>true</turnGravityOff>
  </gazebo>
  <link name="base_laser_bottom">
    <visual>
      <origin rpy="0 0 0" xyz="0 0 0"/>
      <geometry>
        <box size="0.05 0.05 0.035"/>
      </geometry>
      <material name="black1">
        <color rgba="0.2 0.2 0.2 1.0"/>
      </material>
    </visual>
    <collision>
      <origin rpy="0 0 0" xyz="0 0 0"/>
      <geometry>
        <box size="0.05 0.05 0.035"/>
      </geometry>
    </collision>
    <inertial>
      <mass value="0.1"/>
      <inertia ixx="0.001" ixy="0.0" ixz="0.0" iyy="0.001" iyz="0.0" izz="0.001"/>
    </inertial>
  </link>
  <gazebo reference="base_laser_bottom">
    <material>Gazebo/FlatBlack</material>
    <selfCollide>false</selfCollide>
    <turnGravityOff>true</turnGravityOff>
  </gazebo>
  <link name="base_laser">
    <visual>
      <origin rpy="0 0 0" xyz="0 0 0"/>
      <geometry>
        <cylinder length="0.035" radius="0.025"/>
      </geometry>
      <material name="black1">
        <color rgba="0.2 0.2 0.2 1.0"/>
      </material>
    </visual>
    <collision>
      <origin rpy="0 0 0" xyz="0 0 0"/>
      <geometry>
        <cylinder length="0.035" radius="0.025"/>
      </geometry>
    </collision>
    <inertial>
      <mass value="0.1"/>
      <inertia ixx="0.001" ixy="0.0" ixz="0.0" iyy="0.001" iyz="0.0" izz="0.001"/>
    </inertial>
  </link>
  <gazebo reference="base_laser">
    <material>Gazebo/Grey</material>
    <selfCollide>false</selfCollide>
    <turnGravityOff>true</turnGravityOff>
  </gazebo>
  <link name="cpu_link">
    <visual>
      <origin rpy="0 0 0" xyz="0 0 0"/>
      <geometry>
        <box size="0.32 0.26 0.040"/>
      </geometry>
      <material name="black1">
        <color rgba="0.2 0.2 0.2 1.0"/>
      </material>
    </visual>
    <collision>
      <origin rpy="0 0 0" xyz="0 0 0"/>
      <geometry>
        <box size="0.32 0.26 0.040"/>
      </geometry>
    </collision>
    <inertial>
      <mass value="0.5"/>
      <inertia ixx="0.001" ixy="0.0" ixz="0.0" iyy="0.001" iyz="0.0" izz="0.001"/>
    </inertial>
  </link>
  <gazebo reference="cpu_link">
    <material>Gazebo/FlatBlack</material>
    <selfCollide>false</selfCollide>
    <turnGravityOff>true</turnGravityOff>
  </gazebo>
  <link name="upper_base_link">
    <visual>
      <origin rpy="0 0 0" xyz="0 0 0"/>
      <geometry>
        <cylinder length="0.1" radius="0.085"/>
      </geometry>
      <material name="grey2">
        <color rgba="0.6 0.6 0.6 1.0"/>
      </material>
    </visual>
    <collision>
      <origin rpy="0 0 0" xyz="0 0 0"/>
      <geometry>
        <cylinder length="0.1" radius="0.085"/>
      </geometry>
    </collision>
    <inertial>
      <mass value="0.25"/>
      <inertia ixx="0.001" ixy="0.0" ixz="0.0" iyy="0.001" iyz="0.0" izz="0.001"/>
    </inertial>
  </link>
  <gazebo reference="upper_base_link">
    <material>Gazebo/BlueTransparent</material>
    <selfCollide>false</selfCollide>
    <turnGravityOff>true</turnGravityOff>
  </gazebo>
  <link name="lower_torso_link">
    <visual>
      <origin rpy="0 0 0" xyz="0 0 0"/>
      <geometry>
        <cylinder length="0.145" radius="0.0375"/>
      </geometry>
      <material name="black1">
        <color rgba="0.2 0.2 0.2 1.0"/>
      </material>
    </visual>
    <collision>
      <origin rpy="0 0 0" xyz="0 0 0"/>
      <geometry>
        <cylinder length="0.145" radius="0.0375"/>
      </geometry>
    </collision>
    <inertial>
      <mass value="0.12"/>
      <inertia ixx="0.001" ixy="0.0" ixz="0.0" iyy="0.001" iyz="0.0" izz="0.001"/>
    </inertial>
  </link>
  <gazebo reference="lower_torso_link">
    <material>Gazebo/WhiteEmissive</material>
    <selfCollide>false</selfCollide>
    <turnGravityOff>true</turnGravityOff>
  </gazebo>
  <link name="upper_torso_link">
    <visual>
      <origin rpy="0 0 0" xyz="0 0 0"/>
      <geometry>
        <cylinder length="0.08" radius="0.045"/>
      </geometry>
      <material name="grey3">
        <color rgba="0.8 0.8 0.8 1.0"/>
      </material>
    </visual>
    <collision>
      <origin rpy="0 0 0" xyz="0 0 0"/>
      <geometry>
        <cylinder length="0.08" radius="0.045"/>
      </geometry>
    </collision>
    <inertial>
      <mass value="0.12"/>
      <inertia ixx="0.001" ixy="0.0" ixz="0.0" iyy="0.001" iyz="0.0" izz="0.001"/>
    </inertial>
  </link>
  <gazebo reference="upper_torso_link">
    <material>Gazebo/BlueTransparent</material>
    <selfCollide>false</selfCollide>
    <turnGravityOff>true</turnGravityOff>
  </gazebo>
  <link name="head_pan_link">
    <visual>
      <origin rpy="0 0 0" xyz="0 0 0"/>
      <geometry>
        <box size="0.05 0.035 0.045"/>
      </geometry>
      <material name="ax12_color">
        <color rgba="0.1 0.1 0.1 1.0"/>
      </material>
    </visual>
    <collision>
      <origin rpy="0 0 0" xyz="0 0 0"/>
      <geometry>
        <box size="0.05 0.035 0.045"/>
      </geometry>
    </collision>
    <inertial>
      <mass value="0.055"/>
      <inertia ixx="0.001" ixy="0.0" ixz="0.0" iyy="0.001" iyz="0.0" izz="0.001"/>
    </inertial>
  </link>
  <gazebo reference="head_pan_link">
    <material>Gazebo/FlatBlack</material>
    <selfCollide>false</selfCollide>
    <turnGravityOff>true</turnGravityOff>
  </gazebo>
  <link name="head_tilt_link">
    <visual>
      <origin rpy="0 0 0" xyz="0 0 0"/>
      <geometry>
        <box size="0.03 0.038 0.04"/>
      </geometry>
      <material name="ax12_color">
        <color rgba="0.1 0.1 0.1 1.0"/>
      </material>
    </visual>
    <collision>
      <origin rpy="0 0 0" xyz="0 0 0"/>
      <geometry>
        <box size="0.03 0.038 0.04"/>
      </geometry>
    </collision>
    <inertial>
      <mass value="0.055"/>
      <inertia ixx="0.001" ixy="0.0" ixz="0.0" iyy="0.001" iyz="0.0" izz="0.001"/>
    </inertial>
  </link>
  <gazebo reference="head_tilt_link">
    <material>Gazebo/FlatBlack</material>
    <selfCollide>false</selfCollide>
    <turnGravityOff>true</turnGravityOff>
  </gazebo>
  <link name="neck_link">
    <visual>
      <origin rpy="0 0 0" xyz="0 0 0"/>
      <geometry>
        <box size="0.028 0.048 0.068"/>
      </geometry>
      <material name="bracket_color">
        <color rgba="0.9 0.9 0.9 1.0"/>
      </material>
    </visual>
    <collision>
      <origin rpy="0 0 0" xyz="0 0 0"/>
      <geometry>
        <box size="0.028 0.048 0.068"/>
      </geometry>
    </collision>
    <inertial>
      <mass value="0.05"/>
      <inertia ixx="0.001" ixy="0.0" ixz="0.0" iyy="0.001" iyz="0.0" izz="0.001"/>
    </inertial>
  </link>
  <gazebo reference="neck_link">
    <material>Gazebo/WhiteEmissive</material>
    <selfCollide>false</selfCollide>
    <turnGravityOff>true</turnGravityOff>
  </gazebo>
  <link name="head_base_link">
    <visual>
      <origin rpy="0 0 0" xyz="0 0 00"/>
      <geometry>
        <box size="0.06 0.08 0.02"/>
      </geometry>
      <material name="black">
        <color rgba="0.1 0.1 0.1 1.0"/>
      </material>
    </visual>
    <collision>
      <origin rpy="0 0 0" xyz="0 0 00"/>
      <geometry>
        <box size="0.06 0.08 0.02"/>
      </geometry>
    </collision>
    <inertial>
      <mass value="0.1"/>
      <inertia ixx="0.001" ixy="0.0" ixz="0.0" iyy="0.001" iyz="0.0" izz="0.001"/>
    </inertial>
  </link>
  <gazebo reference="head_base_link">
    <material>Gazebo/FlatBlack</material>
    <selfCollide>false</selfCollide>
    <turnGravityOff>true</turnGravityOff>
  </gazebo>
  <link name="head_post_link">
    <visual>
      <origin rpy="0 0 0" xyz="0 0 00"/>
      <geometry>
        <cylinder length="0.012" radius="0.005"/>
      </geometry>
      <material name="grey3">
        <color rgba="0.8 0.8 0.8 1.0"/>
      </material>
    </visual>
    <collision>
      <origin rpy="0 0 0" xyz="0 0 00"/>
      <geometry>
        <cylinder length="0.012" radius="0.005"/>
      </geometry>
    </collision>
    <inertial>
      <mass value="0.1"/>
      <inertia ixx="0.001" ixy="0.0" ixz="0.0" iyy="0.001" iyz="0.0" izz="0.001"/>
    </inertial>
  </link>
  <gazebo reference="head_post_link">
    <material>Gazebo/WhiteEmissive</material>
    <selfCollide>false</selfCollide>
    <turnGravityOff>true</turnGravityOff>
  </gazebo>
  <link name="head_link">
    <visual>
      <origin rpy="0 0 0" xyz="0 0 00"/>
      <geometry>
        <box size="0.06 0.26 0.035"/>
      </geometry>
      <material name="black">
        <color rgba="0.1 0.1 0.1 1.0"/>
      </material>
    </visual>
    <collision>
      <origin rpy="0 0 0" xyz="0 0 00"/>
      <geometry>
        <box size="0.06 0.26 0.035"/>
      </geometry>
    </collision>
    <inertial>
      <mass value="0.8"/>
      <inertia ixx="0.001" ixy="0.0" ixz="0.0" iyy="0.001" iyz="0.0" izz="0.001"/>
    </inertial>
  </link>
  <gazebo reference="head_link">
    <material>Gazebo/FlatBlack</material>
    <selfCollide>false</selfCollide>
    <turnGravityOff>true</turnGravityOff>
  </gazebo>
  <link name="left_eye_link">
    <visual>
      <origin rpy="0 0 0" xyz="0 0 00"/>
      <geometry>
        <cylinder length="0.01" radius="0.01"/>
      </geometry>
      <material name="grey3">
        <color rgba="0.8 0.8 0.8 1.0"/>
      </material>
    </visual>
    <collision>
      <origin rpy="0 0 0" xyz="0 0 00"/>
      <geometry>
        <cylinder length="0.01" radius="0.01"/>
      </geometry>
    </collision>
    <inertial>
      <mass value="0.001"/>
      <inertia ixx="0.001" ixy="0.0" ixz="0.0" iyy="0.001" iyz="0.0" izz="0.001"/>
    </inertial>
  </link>
  <gazebo reference="left_eye_link">
    <material>Gazebo/WhiteEmissive</material>
    <selfCollide>false</selfCollide>
    <turnGravityOff>true</turnGravityOff>
  </gazebo>
  <link name="right_eye_link">
    <visual>
      <origin rpy="0 0 0" xyz="0 0 00"/>
      <geometry>
        <cylinder length="0.01" radius="0.01"/>
      </geometry>
      <material name="grey3">
        <color rgba="0.8 0.8 0.8 1.0"/>
      </material>
    </visual>
    <collision>
      <origin rpy="0 0 0" xyz="0 0 00"/>
      <geometry>
        <cylinder length="0.01" radius="0.01"/>
      </geometry>
    </collision>
    <inertial>
      <mass value="0.001"/>
      <inertia ixx="0.001" ixy="0.0" ixz="0.0" iyy="0.001" iyz="0.0" izz="0.001"/>
    </inertial>
  </link>
  <gazebo reference="right_eye_link">
    <material>Gazebo/WhiteEmissive</material>
    <selfCollide>false</selfCollide>
    <turnGravityOff>true</turnGravityOff>
  </gazebo>
  <link name="hair_link">
    <visual>
      <origin rpy="0 0 0" xyz="0 0 0"/>
      <geometry>
        <box size="0.005 0.04 0.05"/>
      </geometry>
      <material name="grey2">
        <color rgba="0.6 0.6 0.6 1.0"/>
      </material>
    </visual>
    <collision>
      <origin rpy="0 0 0" xyz="0 0 0"/>
      <geometry>
        <box size="0.005 0.04 0.05"/>
      </geometry>
    </collision>
    <inertial>
      <mass value="0.05"/>
      <inertia ixx="0.001" ixy="0.0" ixz="0.0" iyy="0.001" iyz="0.0" izz="0.001"/>
    </inertial>
  </link>
  <gazebo reference="hair_link">
    <material>Gazebo/WhiteEmissive</material>
    <selfCollide>false</selfCollide>
    <turnGravityOff>true</turnGravityOff>
  </gazebo>
  <!-- ============================   Arms   ============================ -->
  <link name="left_shoulder_link">
    <visual>
      <origin rpy="0 0 0" xyz="0 0.02 0"/>
      <geometry>
        <box size="0.025 0.04 0.05"/>
      </geometry>
      <material name="bracket_color">
        <color rgba="0.9 0.9 0.9 1.0"/>
      </material>
    </visual>
    <collision>
      <origin rpy="0 0 0" xyz="0 0.02 0"/>
      <geometry>
        <box size="0.025 0.04 0.05"/>
      </geometry>
    </collision>
    <inertial>
      <mass value="0.05"/>
      <inertia ixx="0.001" ixy="0.0" ixz="0.0" iyy="0.001" iyz="0.0" izz="0.001"/>
    </inertial>
  </link>
  <gazebo reference="left_shoulder_link">
    <material>Gazebo/WhiteEmissive</material>
    <selfCollide>false</selfCollide>
    <turnGravityOff>true</turnGravityOff>
  </gazebo>
  <link name="left_shoulder_pan_link">
    <visual>
      <origin rpy="0 0 0" xyz="0 0.012 0"/>
      <geometry>
        <box size="0.03 0.058 0.03"/>
      </geometry>
      <material name="ax12_color">
        <color rgba="0.1 0.1 0.1 1.0"/>
      </material>
    </visual>
    <collision>
      <origin rpy="0 0 0" xyz="0 0.012 0"/>
      <geometry>
        <box size="0.03 0.058 0.03"/>
      </geometry>
    </collision>
    <inertial>
      <mass value="0.055"/>
      <inertia ixx="0.001" ixy="0.0" ixz="0.0" iyy="0.001" iyz="0.0" izz="0.001"/>
    </inertial>
  </link>
  <gazebo reference="left_shoulder_pan_link">
    <material>Gazebo/FlatBlack</material>
    <selfCollide>false</selfCollide>
    <turnGravityOff>true</turnGravityOff>
  </gazebo>
  <link name="left_shoulder_lift_link">
    <visual>
      <origin rpy="0 0 0" xyz="0 0.009 -0.018"/>
      <geometry>
        <box size="0.03 0.03 0.052"/>
      </geometry>
      <material name="ax12_color">
        <color rgba="0.1 0.1 0.1 1.0"/>
      </material>
    </visual>
    <collision>
      <origin rpy="0 0 0" xyz="0 0.009 -0.018"/>
      <geometry>
        <box size="0.03 0.03 0.052"/>
      </geometry>
    </collision>
    <inertial>
      <mass value="0.055"/>
      <inertia ixx="0.001" ixy="0.0" ixz="0.0" iyy="0.001" iyz="0.0" izz="0.001"/>
    </inertial>
  </link>
  <gazebo reference="left_shoulder_lift_link">
    <material>Gazebo/FlatBlack</material>
    <selfCollide>false</selfCollide>
    <turnGravityOff>true</turnGravityOff>
  </gazebo>
  <link name="left_upper_arm_bracket_link">
    <visual>
      <origin rpy="0 0 0" xyz="0 0 0"/>
      <geometry>
        <box size="0.03 0.03 0.005"/>
      </geometry>
      <material name="bracket_color">
        <color rgba="0.9 0.9 0.9 1.0"/>
      </material>
    </visual>
    <collision>
      <origin rpy="0 0 0" xyz="0 0 0"/>
      <geometry>
        <box size="0.03 0.03 0.005"/>
      </geometry>
    </collision>
    <inertial>
      <mass value="0.02"/>
      <inertia ixx="0.001" ixy="0.0" ixz="0.0" iyy="0.001" iyz="0.0" izz="0.001"/>
    </inertial>
  </link>
  <gazebo reference="left_upper_arm_bracket_link">
    <material>Gazebo/WhiteEmissive</material>
    <selfCollide>false</selfCollide>
    <turnGravityOff>true</turnGravityOff>
  </gazebo>
  <link name="left_arm_roll_link">
    <visual>
      <origin rpy="0 0 0" xyz="-0.013 0.009 0"/>
      <geometry>
        <box size="0.05 0.03 0.03"/>
      </geometry>
      <material name="ax12_color">
        <color rgba="0.1 0.1 0.1 1.0"/>
      </material>
    </visual>
    <collision>
      <origin rpy="0 0 0" xyz="-0.013 0.009 0"/>
      <geometry>
        <box size="0.05 0.03 0.03"/>
      </geometry>
    </collision>
    <inertial>
      <mass value="0.055"/>
      <inertia ixx="0.001" ixy="0.0" ixz="0.0" iyy="0.001" iyz="0.0" izz="0.001"/>
    </inertial>
  </link>
  <gazebo reference="left_arm_roll_link">
    <material>Gazebo/FlatBlack</material>
    <selfCollide>false</selfCollide>
    <turnGravityOff>true</turnGravityOff>
  </gazebo>
  <link name="left_upper_elbow_bracket_link">
    <visual>
      <origin rpy="0 0 0" xyz="0 0 0"/>
      <geometry>
        <box size="0.03 0.022 0.005"/>
      </geometry>
      <material name="bracket_color">
        <color rgba="0.9 0.9 0.9 1.0"/>
      </material>
    </visual>
    <collision>
      <origin rpy="0 0 0" xyz="0 0 0"/>
      <geometry>
        <box size="0.03 0.022 0.005"/>
      </geometry>
    </collision>
    <inertial>
      <mass value="0.02"/>
      <inertia ixx="0.001" ixy="0.0" ixz="0.0" iyy="0.001" iyz="0.0" izz="0.001"/>
    </inertial>
  </link>
  <gazebo reference="left_upper_elbow_bracket_link">
    <material>Gazebo/WhiteEmissive</material>
    <selfCollide>false</selfCollide>
    <turnGravityOff>true</turnGravityOff>
  </gazebo>
  <link name="left_elbow_servo_link">
    <visual>
      <origin rpy="0 0 0" xyz="0 0 0"/>
      <geometry>
        <box size="0.03 0.03 0.05"/>
      </geometry>
      <material name="ax12_color">
        <color rgba="0.1 0.1 0.1 1.0"/>
      </material>
    </visual>
    <collision>
      <origin rpy="0 0 0" xyz="0 0 0"/>
      <geometry>
        <box size="0.03 0.03 0.05"/>
      </geometry>
    </collision>
    <inertial>
      <mass value="0.055"/>
      <inertia ixx="0.001" ixy="0.0" ixz="0.0" iyy="0.001" iyz="0.0" izz="0.001"/>
    </inertial>
  </link>
  <gazebo reference="left_elbow_servo_link">
    <material>Gazebo/FlatBlack</material>
    <selfCollide>false</selfCollide>
    <turnGravityOff>true</turnGravityOff>
  </gazebo>
  <link name="left_elbow_link">
    <visual>
      <origin rpy="0 0 0" xyz="0 0 -0.021"/>
      <geometry>
        <box size="0.05 0.025 0.038"/>
      </geometry>
      <material name="bracket_color">
        <color rgba="0.9 0.9 0.9 1.0"/>
      </material>
    </visual>
    <collision>
      <origin rpy="0 0 0" xyz="0 0 -0.021"/>
      <geometry>
        <box size="0.05 0.025 0.038"/>
      </geometry>
    </collision>
    <inertial>
      <mass value="0.05"/>
      <inertia ixx="0.001" ixy="0.0" ixz="0.0" iyy="0.001" iyz="0.0" izz="0.001"/>
    </inertial>
  </link>
  <gazebo reference="left_elbow_link">
    <material>Gazebo/WhiteEmissive</material>
    <selfCollide>false</selfCollide>
    <turnGravityOff>true</turnGravityOff>
  </gazebo>
  <link name="left_lower_arm_link">
    <visual>
      <origin rpy="0 0 0" xyz="0.0015 0 -0.048"/>
      <geometry>
        <cylinder length="0.092" radius="0.006"/>
      </geometry>
      <material name="grey1">
        <color rgba="0.9 0.9 0.9 1.0"/>
      </material>
    </visual>
    <collision>
      <origin rpy="0 0 0" xyz="0.0015 0 -0.048"/>
      <geometry>
        <cylinder length="0.092" radius="0.006"/>
      </geometry>
    </collision>
    <inertial>
      <mass value="0.2"/>
      <inertia ixx="0.001" ixy="0.0" ixz="0.0" iyy="0.001" iyz="0.0" izz="0.001"/>
    </inertial>
  </link>
  <gazebo reference="left_lower_arm_link">
    <material>Gazebo/Chrome</material>
    <selfCollide>false</selfCollide>
    <turnGravityOff>true</turnGravityOff>
  </gazebo>
  <link name="left_wrist_bracket_link">
    <visual>
      <origin rpy="0 0 0" xyz="0 0 -0.021"/>
      <geometry>
        <box size="0.05 0.025 0.038"/>
      </geometry>
      <material name="bracket_color">
        <color rgba="0.9 0.9 0.9 1.0"/>
      </material>
    </visual>
    <collision>
      <origin rpy="0 0 0" xyz="0 0 -0.021"/>
      <geometry>
        <box size="0.05 0.025 0.038"/>
      </geometry>
    </collision>
    <inertial>
      <mass value="0.02"/>
      <inertia ixx="0.001" ixy="0.0" ixz="0.0" iyy="0.001" iyz="0.0" izz="0.001"/>
    </inertial>
  </link>
  <gazebo reference="left_wrist_bracket_link">
    <material>Gazebo/WhiteEmissive</material>
    <selfCollide>false</selfCollide>
    <turnGravityOff>true</turnGravityOff>
  </gazebo>
  <link name="left_wrist_link">
    <visual>
      <origin rpy="0 0 0" xyz="0 0 -0.016"/>
      <geometry>
        <box size="0.03 0.03 0.05"/>
      </geometry>
      <material name="ax12_color">
        <color rgba="0.1 0.1 0.1 1.0"/>
      </material>
    </visual>
    <collision>
      <origin rpy="0 0 0" xyz="0 0 -0.016"/>
      <geometry>
        <box size="0.03 0.03 0.05"/>
      </geometry>
    </collision>
    <inertial>
      <mass value="0.055"/>
      <inertia ixx="0.001" ixy="0.0" ixz="0.0" iyy="0.001" iyz="0.0" izz="0.001"/>
    </inertial>
  </link>
  <gazebo reference="left_wrist_link">
    <material>Gazebo/FlatBlack</material>
    <selfCollide>false</selfCollide>
    <turnGravityOff>true</turnGravityOff>
  </gazebo>
  <link name="left_hand_link">
    <visual>
      <origin rpy="0 0 0" xyz="0 0 -0.032"/>
      <geometry>
        <box size="0.03 0.01 0.064"/>
      </geometry>
      <material name="grey1">
        <color rgba="0.9 0.9 0.9 1.0"/>
      </material>
    </visual>
    <collision>
      <origin rpy="0 0 0" xyz="0 0 -0.032"/>
      <geometry>
        <box size="0.03 0.01 0.064"/>
      </geometry>
    </collision>
    <inertial>
      <mass value="0.1"/>
      <inertia ixx="0.001" ixy="0.0" ixz="0.0" iyy="0.001" iyz="0.0" izz="0.001"/>
    </inertial>
  </link>
  <gazebo reference="left_hand_link">
    <material>Gazebo/WhiteEmissive</material>
    <selfCollide>false</selfCollide>
    <turnGravityOff>true</turnGravityOff>
  </gazebo>
  <link name="left_finger_link">
    <visual>
      <origin rpy="0 0 0" xyz="0 0 0"/>
      <geometry>
        <box size="0.01 0.01 0.005"/>
      </geometry>
      <material name="black1">
        <color rgba="0.2 0.2 0.2 1.0"/>
      </material>
    </visual>
    <collision>
      <origin rpy="0 0 0" xyz="0 0 0"/>
      <geometry>
        <box size="0.01 0.01 0.005"/>
      </geometry>
    </collision>
    <inertial>
      <mass value="0.001"/>
      <inertia ixx="0.001" ixy="0.0" ixz="0.0" iyy="0.001" iyz="0.0" izz="0.001"/>
    </inertial>
  </link>
  <gazebo reference="left_finger_link">
    <material>Gazebo/WhiteEmissive</material>
    <selfCollide>false</selfCollide>
    <turnGravityOff>true</turnGravityOff>
  </gazebo>
  <link name="right_shoulder_link">
    <visual>
      <origin rpy="0 0 0" xyz="0 -0.02 0"/>
      <geometry>
        <box size="0.025 0.04 0.05"/>
      </geometry>
      <material name="bracket_color">
        <color rgba="0.9 0.9 0.9 1.0"/>
      </material>
    </visual>
    <collision>
      <origin rpy="0 0 0" xyz="0 -0.02 0"/>
      <geometry>
        <box size="0.025 0.04 0.05"/>
      </geometry>
    </collision>
    <inertial>
      <mass value="0.05"/>
      <inertia ixx="0.001" ixy="0.0" ixz="0.0" iyy="0.001" iyz="0.0" izz="0.001"/>
    </inertial>
  </link>
  <gazebo reference="right_shoulder_link">
    <material>Gazebo/WhiteEmissive</material>
    <selfCollide>false</selfCollide>
    <turnGravityOff>true</turnGravityOff>
  </gazebo>
  <link name="right_shoulder_pan_link">
    <visual>
      <origin rpy="0 0 0" xyz="0 -0.012 0"/>
      <geometry>
        <box size="0.03 0.058 0.03"/>
      </geometry>
      <material name="ax12_color">
        <color rgba="0.1 0.1 0.1 1.0"/>
      </material>
    </visual>
    <collision>
      <origin rpy="0 0 0" xyz="0 -0.012 0"/>
      <geometry>
        <box size="0.03 0.058 0.03"/>
      </geometry>
    </collision>
    <inertial>
      <mass value="0.055"/>
      <inertia ixx="0.001" ixy="0.0" ixz="0.0" iyy="0.001" iyz="0.0" izz="0.001"/>
    </inertial>
  </link>
  <gazebo reference="right_shoulder_pan_link">
    <material>Gazebo/FlatBlack</material>
    <selfCollide>false</selfCollide>
    <turnGravityOff>true</turnGravityOff>
  </gazebo>
  <link name="right_shoulder_lift_link">
    <visual>
      <origin rpy="0 0 0" xyz="0 -0.009 -0.018"/>
      <geometry>
        <box size="0.03 0.03 0.052"/>
      </geometry>
      <material name="ax12_color">
        <color rgba="0.1 0.1 0.1 1.0"/>
      </material>
    </visual>
    <collision>
      <origin rpy="0 0 0" xyz="0 -0.009 -0.018"/>
      <geometry>
        <box size="0.03 0.03 0.052"/>
      </geometry>
    </collision>
    <inertial>
      <mass value="0.055"/>
      <inertia ixx="0.001" ixy="0.0" ixz="0.0" iyy="0.001" iyz="0.0" izz="0.001"/>
    </inertial>
  </link>
  <gazebo reference="right_shoulder_lift_link">
    <material>Gazebo/FlatBlack</material>
    <selfCollide>false</selfCollide>
    <turnGravityOff>true</turnGravityOff>
  </gazebo>
  <link name="right_upper_arm_bracket_link">
    <visual>
      <origin rpy="0 0 0" xyz="0 0 0"/>
      <geometry>
        <box size="0.03 0.03 0.005"/>
      </geometry>
      <material name="bracket_color">
        <color rgba="0.9 0.9 0.9 1.0"/>
      </material>
    </visual>
    <collision>
      <origin rpy="0 0 0" xyz="0 0 0"/>
      <geometry>
        <box size="0.03 0.03 0.005"/>
      </geometry>
    </collision>
    <inertial>
      <mass value="0.02"/>
      <inertia ixx="0.001" ixy="0.0" ixz="0.0" iyy="0.001" iyz="0.0" izz="0.001"/>
    </inertial>
  </link>
  <gazebo reference="right_upper_arm_bracket_link">
    <material>Gazebo/WhiteEmissive</material>
    <selfCollide>false</selfCollide>
    <turnGravityOff>true</turnGravityOff>
  </gazebo>
  <link name="right_arm_roll_link">
    <visual>
      <origin rpy="0 0 0" xyz="-0.013 -0.009 0"/>
      <geometry>
        <box size="0.05 0.03 0.03"/>
      </geometry>
      <material name="ax12_color">
        <color rgba="0.1 0.1 0.1 1.0"/>
      </material>
    </visual>
    <collision>
      <origin rpy="0 0 0" xyz="-0.013 -0.009 0"/>
      <geometry>
        <box size="0.05 0.03 0.03"/>
      </geometry>
    </collision>
    <inertial>
      <mass value="0.055"/>
      <inertia ixx="0.001" ixy="0.0" ixz="0.0" iyy="0.001" iyz="0.0" izz="0.001"/>
    </inertial>
  </link>
  <gazebo reference="right_arm_roll_link">
    <material>Gazebo/FlatBlack</material>
    <selfCollide>false</selfCollide>
    <turnGravityOff>true</turnGravityOff>
  </gazebo>
  <link name="right_upper_elbow_bracket_link">
    <visual>
      <origin rpy="0 0 0" xyz="0 0 0"/>
      <geometry>
        <box size="0.03 0.022 0.005"/>
      </geometry>
      <material name="bracket_color">
        <color rgba="0.9 0.9 0.9 1.0"/>
      </material>
    </visual>
    <collision>
      <origin rpy="0 0 0" xyz="0 0 0"/>
      <geometry>
        <box size="0.03 0.022 0.005"/>
      </geometry>
    </collision>
    <inertial>
      <mass value="0.02"/>
      <inertia ixx="0.001" ixy="0.0" ixz="0.0" iyy="0.001" iyz="0.0" izz="0.001"/>
    </inertial>
  </link>
  <gazebo reference="right_upper_elbow_bracket_link">
    <material>Gazebo/WhiteEmissive</material>
    <selfCollide>false</selfCollide>
    <turnGravityOff>true</turnGravityOff>
  </gazebo>
  <link name="right_elbow_servo_link">
    <visual>
      <origin rpy="0 0 0" xyz="0 0 0"/>
      <geometry>
        <box size="0.03 0.03 0.05"/>
      </geometry>
      <material name="ax12_color">
        <color rgba="0.1 0.1 0.1 1.0"/>
      </material>
    </visual>
    <collision>
      <origin rpy="0 0 0" xyz="0 0 0"/>
      <geometry>
        <box size="0.03 0.03 0.05"/>
      </geometry>
    </collision>
    <inertial>
      <mass value="0.055"/>
      <inertia ixx="0.001" ixy="0.0" ixz="0.0" iyy="0.001" iyz="0.0" izz="0.001"/>
    </inertial>
  </link>
  <gazebo reference="right_elbow_servo_link">
    <material>Gazebo/FlatBlack</material>
    <selfCollide>false</selfCollide>
    <turnGravityOff>true</turnGravityOff>
  </gazebo>
  <link name="right_elbow_link">
    <visual>
      <origin rpy="0 0 0" xyz="0 0 -0.021"/>
      <geometry>
        <box size="0.05 0.025 0.038"/>
      </geometry>
      <material name="bracket_color">
        <color rgba="0.9 0.9 0.9 1.0"/>
      </material>
    </visual>
    <collision>
      <origin rpy="0 0 0" xyz="0 0 -0.021"/>
      <geometry>
        <box size="0.05 0.025 0.038"/>
      </geometry>
    </collision>
    <inertial>
      <mass value="0.05"/>
      <inertia ixx="0.001" ixy="0.0" ixz="0.0" iyy="0.001" iyz="0.0" izz="0.001"/>
    </inertial>
  </link>
  <gazebo reference="right_elbow_link">
    <material>Gazebo/WhiteEmissive</material>
    <selfCollide>false</selfCollide>
    <turnGravityOff>true</turnGravityOff>
  </gazebo>
  <link name="right_lower_arm_link">
    <visual>
      <origin rpy="0 0 0" xyz="0.0015 0 -0.048"/>
      <geometry>
        <cylinder length="0.092" radius="0.006"/>
      </geometry>
      <material name="grey1">
        <color rgba="0.9 0.9 0.9 1.0"/>
      </material>
    </visual>
    <collision>
      <origin rpy="0 0 0" xyz="0.0015 0 -0.048"/>
      <geometry>
        <cylinder length="0.092" radius="0.006"/>
      </geometry>
    </collision>
    <inertial>
      <mass value="0.2"/>
      <inertia ixx="0.001" ixy="0.0" ixz="0.0" iyy="0.001" iyz="0.0" izz="0.001"/>
    </inertial>
  </link>
  <gazebo reference="right_lower_arm_link">
    <material>Gazebo/Chrome</material>
    <selfCollide>false</selfCollide>
    <turnGravityOff>true</turnGravityOff>
  </gazebo>
  <link name="right_wrist_bracket_link">
    <visual>
      <origin rpy="0 0 0" xyz="0 0 -0.021"/>
      <geometry>
        <box size="0.05 0.025 0.038"/>
      </geometry>
      <material name="bracket_color">
        <color rgba="0.9 0.9 0.9 1.0"/>
      </material>
    </visual>
    <collision>
      <origin rpy="0 0 0" xyz="0 0 -0.021"/>
      <geometry>
        <box size="0.05 0.025 0.038"/>
      </geometry>
    </collision>
    <inertial>
      <mass value="0.02"/>
      <inertia ixx="0.001" ixy="0.0" ixz="0.0" iyy="0.001" iyz="0.0" izz="0.001"/>
    </inertial>
  </link>
  <gazebo reference="right_wrist_bracket_link">
    <material>Gazebo/WhiteEmissive</material>
    <selfCollide>false</selfCollide>
    <turnGravityOff>true</turnGravityOff>
  </gazebo>
  <link name="right_wrist_link">
    <visual>
      <origin rpy="0 0 0" xyz="0 0 -0.016"/>
      <geometry>
        <box size="0.03 0.03 0.05"/>
      </geometry>
      <material name="ax12_color">
        <color rgba="0.1 0.1 0.1 1.0"/>
      </material>
    </visual>
    <collision>
      <origin rpy="0 0 0" xyz="0 0 -0.016"/>
      <geometry>
        <box size="0.03 0.03 0.05"/>
      </geometry>
    </collision>
    <inertial>
      <mass value="0.055"/>
      <inertia ixx="0.001" ixy="0.0" ixz="0.0" iyy="0.001" iyz="0.0" izz="0.001"/>
    </inertial>
  </link>
  <gazebo reference="right_wrist_link">
    <material>Gazebo/FlatBlack</material>
    <selfCollide>false</selfCollide>
    <turnGravityOff>true</turnGravityOff>
  </gazebo>
  <link name="right_hand_link">
    <visual>
      <origin rpy="0 0 0" xyz="0 0 -0.032"/>
      <geometry>
        <box size="0.03 0.01 0.064"/>
      </geometry>
      <material name="grey1">
        <color rgba="0.9 0.9 0.9 1.0"/>
      </material>
    </visual>
    <collision>
      <origin rpy="0 0 0" xyz="0 0 -0.032"/>
      <geometry>
        <box size="0.03 0.01 0.064"/>
      </geometry>
    </collision>
    <inertial>
      <mass value="0.1"/>
      <inertia ixx="0.001" ixy="0.0" ixz="0.0" iyy="0.001" iyz="0.0" izz="0.001"/>
    </inertial>
  </link>
  <gazebo reference="right_hand_link">
    <material>Gazebo/WhiteEmissive</material>
    <selfCollide>false</selfCollide>
    <turnGravityOff>true</turnGravityOff>
  </gazebo>
  <link name="right_finger_link">
    <visual>
      <origin rpy="0 0 0" xyz="0 0 0"/>
      <geometry>
        <box size="0.01 0.01 0.005"/>
      </geometry>
      <material name="black1">
        <color rgba="0.2 0.2 0.2 1.0"/>
      </material>
    </visual>
    <collision>
      <origin rpy="0 0 0" xyz="0 0 0"/>
      <geometry>
        <box size="0.01 0.01 0.005"/>
      </geometry>
    </collision>
    <inertial>
      <mass value="0.001"/>
      <inertia ixx="0.001" ixy="0.0" ixz="0.0" iyy="0.001" iyz="0.0" izz="0.001"/>
    </inertial>
  </link>
  <gazebo reference="right_finger_link">
    <material>Gazebo/WhiteEmissive</material>
    <selfCollide>false</selfCollide>
    <turnGravityOff>true</turnGravityOff>
  </gazebo>
  <!-- =================== Joint Definitions ==================== -->
  <!--
	<joint name="base_world_link" type="continuous">
    	<parent link="world"/>
    	<child link="base_link"/>
    	<axis xyz="0 0 0"/>
    	<origin rpy="0 0 0" xyz="0 0 0"/>
    	<dynamics damping="0.05"/>
  	</joint>
  	-->
  <joint name="cpu_joint" type="fixed">
    <parent link="base_link"/>
    <child link="cpu_link"/>
    <origin rpy="0 0 0" xyz="0 0 0.125"/>
  </joint>
  <joint name="base_laser_bottom_joint" type="fixed">
    <parent link="base_link"/>
    <child link="base_laser_bottom"/>
    <origin rpy="0 0 0" xyz="0.21 0 0.053"/>
  </joint>
  <joint name="base_laser_joint" type="fixed">
    <parent link="base_laser_bottom"/>
    <child link="base_laser"/>
    <origin rpy="0 0 0" xyz="0 0 0.035"/>
  </joint>
  <joint name="upper_base_joint" type="fixed">
    <parent link="cpu_link"/>
    <child link="upper_base_link"/>
    <origin rpy="0 0 0" xyz="0.06 0 0.07"/>
  </joint>
  <joint name="torso_joint" type="revolute">
    <parent link="upper_base_link"/>
    <child link="lower_torso_link"/>
    <origin rpy="0 0 0" xyz="0 0 0.1225"/>
    <axis xyz="0 0 1"/>
    <limit effort="10" lower="-3.1416" upper="3.1416" velocity="3"/>
    <dynamics damping="0.0"/>
  </joint>
  <joint name="upper_torso_joint" type="fixed">
    <parent link="lower_torso_link"/>
    <child link="upper_torso_link"/>
    <origin rpy="0 0 0" xyz="0 0 0.1125"/>
  </joint>
  <joint name="head_pan_servo" type="fixed">
    <parent link="upper_torso_link"/>
    <child link="head_pan_link"/>
    <origin rpy="0 0 0" xyz="-0.015 0 0.0625"/>
  </joint>
  <joint name="head_pan_joint" type="revolute">
    <parent link="head_pan_link"/>
    <child link="head_tilt_link"/>
    <origin rpy="0 0 0" xyz="-0.01 0 0.0425"/>
    <axis xyz="0 0 1"/>
    <limit effort="10" lower="-3.1416" upper="3.1416" velocity="3"/>
    <dynamics damping="0.0"/>
  </joint>
  <joint name="head_tilt_joint" type="revolute">
    <parent link="head_tilt_link"/>
    <child link="neck_link"/>
    <origin rpy="0 0 0" xyz="0 0 0.04"/>
    <axis xyz="0 1 0"/>
    <limit effort="10" lower="-1.57" upper="1.57" velocity="3"/>
    <dynamics damping="0.0"/>
  </joint>
  <joint name="neck_joint" type="fixed">
    <parent link="neck_link"/>
    <child link="head_base_link"/>
    <origin rpy="0 0 0" xyz="0 0 0.044"/>
  </joint>
  <joint name="head_base_joint" type="fixed">
    <parent link="head_base_link"/>
    <child link="head_post_link"/>
    <origin rpy="0 0 0" xyz="0 0 0.016"/>
  </joint>
  <joint name="head_joint" type="fixed">
    <parent link="head_post_link"/>
    <child link="head_link"/>
    <origin rpy="0 0 0" xyz="0 0 0.0235"/>
  </joint>
  <joint name="left_eye_joint" type="fixed">
    <parent link="head_link"/>
    <child link="left_eye_link"/>
    <origin rpy="0 1.57 0" xyz="0.026 0.05 0"/>
  </joint>
  <joint name="right_eye_joint" type="fixed">
    <parent link="head_link"/>
    <child link="right_eye_link"/>
    <origin rpy="0 1.57 0" xyz="0.026 -0.05 0"/>
  </joint>
  <joint name="hair_joint" type="fixed">
    <parent link="head_link"/>
    <child link="hair_link"/>
    <origin rpy="0 0 0" xyz="-0.025 0 0.0425"/>
  </joint>
  <joint name="left_shoulder_joint" type="fixed">
    <parent link="lower_torso_link"/>
    <child link="left_shoulder_link"/>
    <origin rpy="0 0 0" xyz="0 0.034 -0.0075"/>
  </joint>
  <joint name="left_shoulder_pan_joint" type="revolute">
    <parent link="left_shoulder_link"/>
    <child link="left_shoulder_pan_link"/>
    <origin rpy="0 0 0" xyz="0 0.031 0"/>
    <limit effort="10" lower="-2.53" upper="2.53" velocity="3"/>
    <axis xyz="0 0 1"/>
    <dynamics damping="0.0"/>
  </joint>
  <joint name="left_shoulder_lift_joint" type="revolute">
    <parent link="left_shoulder_pan_link"/>
    <child link="left_shoulder_lift_link"/>
    <origin rpy="0 -1.57 0" xyz="0 0.047 0"/>
    <limit effort="10" lower="-2.53" upper="2.53" velocity="3"/>
    <axis xyz="0 1 0"/>
    <dynamics damping="0.0"/>
  </joint>
  <joint name="left_upper_arm_bracket_joint" type="fixed">
    <parent link="left_shoulder_lift_link"/>
    <child link="left_upper_arm_bracket_link"/>
    <origin rpy="0 0 0" xyz="0 0.009 -0.0465"/>
  </joint>
  <joint name="left_arm_roll_joint" type="revolute">
    <parent link="left_upper_arm_bracket_link"/>
    <child link="left_arm_roll_link"/>
    <limit effort="10" lower="-2.53" upper="2.53" velocity="3"/>
    <origin rpy="0 0 0" xyz="0 -0.009 -0.0175"/>
    <axis xyz="0 0 -1"/>
    <dynamics damping="0.0"/>
  </joint>
  <joint name="left_upper_elbow_bracket_joint" type="fixed">
    <parent link="left_arm_roll_link"/>
    <child link="left_upper_elbow_bracket_link"/>
    <origin rpy="0 0 -1.57" xyz="-0.012 0.009 -0.0175"/>
    <dynamics damping="0.0"/>
  </joint>
  <joint name="left_elbow_servo_joint" type="fixed">
    <parent link="left_upper_elbow_bracket_link"/>
    <child link="left_elbow_servo_link"/>
    <origin rpy="0 0 1.57" xyz="0 0 -0.0275"/>
    <axis xyz="0 1 0"/>
  </joint>
  <joint name="left_elbow_joint" type="revolute">
    <parent link="left_elbow_servo_link"/>
    <child link="left_elbow_link"/>
    <origin rpy="0 0 0" xyz="0 0 0"/>
    <limit effort="10" lower="-2.53" upper="2.53" velocity="3"/>
    <axis xyz="1 0 0"/>
    <dynamics damping="0.0"/>
  </joint>
  <joint name="left_wrist_bracket_joint" type="fixed">
    <parent link="left_lower_arm_link"/>
    <child link="left_wrist_bracket_link"/>
    <origin rpy="0 0 0" xyz="0 0 -0.092"/>
    <dynamics damping="0.0"/>
  </joint>
  <joint name="left_hand_joint" type="fixed">
    <parent link="left_wrist_link"/>
    <child link="left_hand_link"/>
    <origin rpy="0 0 0" xyz="0 0 -0.041"/>
  </joint>
  <joint name="left_finger_joint" type="fixed">
    <parent link="left_hand_link"/>
    <child link="left_finger_link"/>
    <origin rpy="0 0 0" xyz="0 0 -0.064"/>
    <dynamics damping="0.0"/>
  </joint>
  <joint name="right_shoulder_joint" type="fixed">
    <parent link="lower_torso_link"/>
    <child link="right_shoulder_link"/>
    <origin rpy="0 0 0" xyz="0 -0.034 -.0075"/>
  </joint>
  <joint name="right_shoulder_pan_joint" type="revolute">
    <parent link="right_shoulder_link"/>
    <child link="right_shoulder_pan_link"/>
    <origin rpy="0 0 0" xyz="0 -0.031 0"/>
    <limit effort="10" lower="-2.53" upper="2.53" velocity="3"/>
    <axis xyz="0 0 1"/>
    <dynamics damping="0.0"/>
  </joint>
  <joint name="right_shoulder_lift_joint" type="revolute">
    <parent link="right_shoulder_pan_link"/>
    <child link="right_shoulder_lift_link"/>
    <origin rpy="0 -1.57 0" xyz="0 -0.047 0"/>
    <limit effort="10" lower="-2.53" upper="2.53" velocity="3"/>
    <axis xyz="0 -1 0"/>
    <dynamics damping="0.0"/>
  </joint>
  <joint name="right_upper_arm_bracket_joint" type="fixed">
    <parent link="right_shoulder_lift_link"/>
    <child link="right_upper_arm_bracket_link"/>
    <origin rpy="0 0 0" xyz="0 -0.009 -0.0465"/>
  </joint>
  <joint name="right_arm_roll_joint" type="revolute">
    <parent link="right_upper_arm_bracket_link"/>
    <child link="right_arm_roll_link"/>
    <limit effort="10" lower="-2.53" upper="2.53" velocity="3"/>
    <origin rpy="0 0 0" xyz="0 0.009 -0.0175"/>
    <axis xyz="0 0 -1"/>
    <dynamics damping="0.0"/>
  </joint>
  <joint name="right_upper_elbow_bracket_joint" type="fixed">
    <parent link="right_arm_roll_link"/>
    <child link="right_upper_elbow_bracket_link"/>
    <origin rpy="0 0 -1.57" xyz="-0.012 -0.009 -0.0175"/>
    <dynamics damping="0.0"/>
  </joint>
  <joint name="right_elbow_servo_joint" type="fixed">
    <parent link="right_upper_elbow_bracket_link"/>
    <child link="right_elbow_servo_link"/>
    <origin rpy="0 0 1.57" xyz="0 0 -0.0275"/>
    <axis xyz="0 -1 0"/>
  </joint>
  <joint name="right_elbow_joint" type="revolute">
    <parent link="right_elbow_servo_link"/>
    <child link="right_elbow_link"/>
    <origin rpy="0 0 0" xyz="0 0 0"/>
    <limit effort="10" lower="-2.53" upper="2.53" velocity="3"/>
    <axis xyz="1 0 0"/>
    <dynamics damping="0.0"/>
  </joint>
  <joint name="left_lower_arm_joint" type="fixed">
    <parent link="left_elbow_link"/>
    <child link="left_lower_arm_link"/>
    <origin rpy="0 0 0" xyz="0 0 -0.038"/>
  </joint>
  <joint name="right_lower_arm_joint" type="fixed">
    <parent link="right_elbow_link"/>
    <child link="right_lower_arm_link"/>
    <origin rpy="0 0 0" xyz="0 0 -0.038"/>
    <dynamics damping="0.0"/>
  </joint>
  <joint name="right_wrist_bracket_joint" type="fixed">
    <parent link="right_lower_arm_link"/>
    <child link="right_wrist_bracket_link"/>
    <origin rpy="0 0 0" xyz="0 0 -0.092"/>
  </joint>
  <joint name="left_wrist_joint" type="revolute">
    <parent link="left_wrist_bracket_link"/>
    <child link="left_wrist_link"/>
    <origin rpy="0 0 0" xyz="0 0 -0.026"/>
    <limit effort="10" lower="-2.53" upper="2.53" velocity="3"/>
    <axis xyz="1 0 0"/>
    <dynamics damping="0.0"/>
  </joint>
  <joint name="right_wrist_joint" type="revolute">
    <parent link="right_wrist_bracket_link"/>
    <child link="right_wrist_link"/>
    <origin rpy="0 0 0" xyz="0 0 -0.026"/>
    <limit effort="10" lower="-2.53" upper="2.53" velocity="3"/>
    <axis xyz="1 0 0"/>
    <dynamics damping="0.0"/>
  </joint>
  <joint name="right_hand_joint" type="fixed">
    <parent link="right_wrist_link"/>
    <child link="right_hand_link"/>
    <origin rpy="0 0 0" xyz="0 0 -0.041"/>
  </joint>
  <joint name="right_finger_joint" type="fixed">
    <parent link="right_hand_link"/>
    <child link="right_finger_link"/>
    <origin rpy="0 0 0" xyz="0 0 -0.064"/>
  </joint>
  <gazebo reference="pi_robot">
  	</gazebo>
</robot>

