<?xml version="1.0"?>

<!-- XML namespaces -->
<robot xmlns:sensor="http://playerstage.sourceforge.net/gazebo/xmlschema/#sensor"
       xmlns:controller="http://playerstage.sourceforge.net/gazebo/xmlschema/#controller"
       xmlns:interface="http://playerstage.sourceforge.net/gazebo/xmlschema/#interface"
       xmlns:xacro="http://ros.org/wiki/xacro" 
	   name="pi_robot">

	<!--
	<include filename="$(find pi_robot_description)/urdf/sensors/hokuyo_laser_gazebo.xacro" />
	-->
	<include filename="$(find pr2_description)/urdf/materials.urdf.xacro" />
	<include filename="$(find pr2_description)/urdf/gripper_v0/gripper.urdf.xacro" />
	
	<xacro:macro name="white">
		<material name="white">
			<color rgba="1.0 1.0 1.0 1.0"/>
		</material>
	</xacro:macro>
	
	<xacro:macro name="black">
		<material name="black">
			<color rgba="0.1 0.1 0.1 1.0"/>
		</material>
	</xacro:macro>
	
	<xacro:macro name="grey1">
		<material name="grey1">
			<color rgba="0.41 0.41 0.41 1.0"/>
		</material>
	</xacro:macro>
	
	<xacro:macro name="blue1">
		<material name="blue1">
			<color rgba="0 0 .8 1"/>
		</material>
	</xacro:macro>
	
	<xacro:macro name="green1">
		<material name="green1">
			<color rgba="0 1 0 0.5"/>
		</material>
	</xacro:macro>
	
	<xacro:macro name="red1">
	  <material name="red1">
	    <color rgba="1 0 0 0.5"/>
		</material>
	</xacro:macro>
	
	<xacro:macro name="ax12_color">
		<material name="ax12_color">
			<color rgba="0.1 0.1 0.1 1.0"/>
		</material>
	</xacro:macro>
	
	<xacro:macro name="bracket_color">
		<material name="bracket_color">
			<color rgba="0.9 0.9 0.9 1.0"/>
		</material>
	</xacro:macro>
	
	<xacro:macro name="my_box" params="name lwh xyz rpy mass material *rviz_color">
		<link name="${name}">
			<visual>
				<origin xyz="${xyz}" rpy="${rpy}" />
				<geometry>
					<box size="${lwh}" />
				</geometry>
			    <xacro:insert_block name="rviz_color" />             
             </visual>
             <collision>
				<origin xyz="${xyz}" rpy="${rpy}" />
					<geometry>
						<box size="${lwh}" />
					</geometry>
             </collision>
             <xacro:default_inertial mass="${mass}" />   
        </link>
        <xacro:default_gazebo name="${name}" material="${material}" />
	</xacro:macro>

	<xacro:macro name="my_cylinder" params="name l r xyz rpy mass material *rviz_color">
		<link name="${name}">
			<visual>
				<origin xyz="${xyz}" rpy="${rpy}" />
				<geometry>
					<cylinder length="${l}" radius="${r}"/>
				</geometry>
				<xacro:insert_block name="rviz_color" />             
			</visual>
			<collision>
				<origin xyz="${xyz}" rpy="${rpy}" />
					<geometry>
						<cylinder length="${l}" radius="${r}" />
					</geometry>
			</collision>
			<xacro:default_inertial mass="${mass}" />   
		</link>
        <xacro:default_gazebo name="${name}" material="${material}" />
	</xacro:macro>
	
    <xacro:macro name="default_gazebo" params="name material">
 		<gazebo reference="${name}">
			<material>${material}</material>
			<selfCollide>false</selfCollide>
			<turnGravityOff>true</turnGravityOff>
		</gazebo>
    </xacro:macro>
    
 	<!-- ============================   Body   ============================ -->
 	
 	<!--
 	<link name="world" />
 	-->

	<xacro:my_box name="base_link" lwh="0.36 0.52 0.02" xyz="0 0 0" rpy="0 0 0" mass="0.5" material="Gazebo/WhiteEmissive">
		<xacro:white />
	</xacro:my_box>
	
 	<xacro:my_box name="torso_link" lwh="0.005 0.4 0.75" xyz="0 0 0" rpy="0 0 0" mass="0.5" material="Gazebo/WhiteEmissive">
		<xacro:grey1 />
	</xacro:my_box>
	
	<xacro:my_box name="shoulder_pan_support_link" lwh="0.06 0.04 0.005" xyz="0 0 0" rpy="0 0 0" mass="0.5" material="Gazebo/WhiteEmissive">
		<xacro:blue1 />
	</xacro:my_box>
		
 	<xacro:my_cylinder name="shoulder_pan_link" l="0.2" r="0.05" xyz="0 0 0" rpy="0 0 0" mass="0.5" material="Gazebo/WhiteEmissive">
		<xacro:green1 />
	</xacro:my_cylinder>

	<xacro:my_box name="shoulder_tilt_support_link" lwh="0.035 0.003 0.04" xyz="0 0 0" rpy="0 0 0" mass="0.5" material="Gazebo/WhiteEmissive">
		<xacro:blue1 />
	</xacro:my_box>
	
	<xacro:my_box name="shoulder_tilt_link" lwh="0.01 0.003 0.03" xyz="0 0 -0.015" rpy="0 0 0" mass="0.5" material="Gazebo/WhiteEmissive">
		<xacro:red1 />
	</xacro:my_box>
	
	<xacro:my_cylinder name="upper_arm_link" l="0.27" r="0.025" xyz="0.135 0 0" rpy="0 1.57 0" mass="0.5" material="Gazebo/WhiteEmissive">
		<xacro:red1 />
	</xacro:my_cylinder>
	
	<xacro:my_box name="elbow_tilt_link" lwh="0.01 0.003 0.03" xyz="0.005 0 0" rpy="0 0 0" mass="0.5" material="Gazebo/WhiteEmissive">
		<xacro:blue1 />
	</xacro:my_box>
	
	<xacro:my_cylinder name="forearm_link" l="0.27" r="0.025" xyz="0.135 0 0" rpy="0 1.57 0" mass="0.5" material="Gazebo/WhiteEmissive">
		<xacro:grey1 />
	</xacro:my_cylinder>
	
	<xacro:my_box name="wrist_tilt_link" lwh="0.03 0.003 0.03" xyz="0.005 0 0" rpy="0 0 0" mass="0.5" material="Gazebo/WhiteEmissive">
		<xacro:blue1 />
	</xacro:my_box>
	
	<xacro:pr2_gripper_v0 reflect="-1.0" side="r" parent="wrist_tilt_link"
               screw_reduction="${4.0/1000.0}"
               gear_ratio="${(729.0/25.0)*(22.0/16.0)}"
               theta0="${3.6029*M_PI/180.0}"
               phi0="${29.7089*M_PI/180.0}"
               t0="${-0.1914/1000.0}"
               L0="${37.5528/1000.0}"
               h="${0.0/1000.0}"
               a="${68.3698/1000.0}"
               b="${43.3849/1000.0}"
               r="${91.5/1000.0}" >
	<origin xyz="0 0 0" rpy="0 0 0" />
      </xacro:pr2_gripper_v0>
	
	
	<!-- head links -->
	<xacro:my_cylinder name="lower_neck_link" l="0.16" r="0.025" xyz="0 0 0" rpy="0 0 0" mass="0.05" material="Gazebo/WhiteEmissive">
		<xacro:grey1 />
	</xacro:my_cylinder>
	
	<xacro:my_box name="upper_neck_link" lwh="0.028 0.048 0.037" xyz="0 0 0.01" rpy="0 0 0" mass="0.05" material="Gazebo/WhiteEmissive">
		<xacro:bracket_color />
	</xacro:my_box>
	
	<xacro:my_box name="head_pan_link" lwh="0.05 0.035 0.04" xyz="0 0 0" rpy="0 0 0" mass="0.055" material="Gazebo/FlatBlack">
		<xacro:ax12_color />
	</xacro:my_box>
	
	<xacro:my_box name="head_tilt_link" lwh="0.03 0.038 0.057" xyz="0 0 0" rpy="0 0 0" mass="0.055" material="Gazebo/FlatBlack">
		<xacro:ax12_color />
	</xacro:my_box>
	
	<xacro:my_box name="head_base_link" lwh="0.06 0.08 0.022" xyz="0 0 00" rpy="0 0 0" mass="0.1" material="Gazebo/FlatBlack">
		<xacro:black />
	</xacro:my_box>
	
	<xacro:my_cylinder name="head_post_link" l="0.012" r="0.005" xyz="0 0 00" rpy="0 0 0" mass="0.1" material="Gazebo/WhiteEmissive">
		<xacro:grey1 />
	</xacro:my_cylinder>
	
	<xacro:my_box name="head_link" lwh="0.06 0.26 0.035" xyz="0 0 00" rpy="0 0 0" mass="0.8" material="Gazebo/FlatBlack">
		<xacro:black />
	</xacro:my_box>
	
	<xacro:my_cylinder name="left_eye_link" l="0.01" r="0.01" xyz="0 0 00" rpy="0 0 0" mass="0.001" material="Gazebo/WhiteEmissive">
		<xacro:grey1 />
	</xacro:my_cylinder>
	
	<xacro:my_cylinder name="right_eye_link" l="0.01" r="0.01" xyz="0 0 00" rpy="0 0 0" mass="0.001" material="Gazebo/WhiteEmissive">
		<xacro:grey1 />
	</xacro:my_cylinder>
 	<!-- ============================   Arms   ============================ -->


	
	<!-- =================== Joint Definitions ==================== -->
	
	<!-- head joints -->
	<joint name="lower_neck_joint" type="fixed">
    	<parent link="torso_link" />
    	<child link="lower_neck_link" />
    	<origin xyz="-0.0275 0 0.455" rpy="0 0 0" />
	</joint>
	
	<joint name="head_pan_servo_joint" type="fixed">
    	<parent link="lower_neck_link" />
    	<child link="head_pan_link" />
    	<origin xyz="0.02 0 0.1" rpy="0 0 0" />
	</joint>
	
	<joint name="head_pan_joint" type="revolute">
    	<parent link="head_pan_link" />
    	<child link="head_tilt_link" />
    	<origin xyz="0.01 0 0.048" rpy="0 0 0" />
    	<axis xyz="0 0 1" />
    	<limit lower="-3.1416" upper="3.1416" effort="10" velocity="3" />
      	<dynamics damping="0.0"/>
	</joint>
  	
 	<joint name="head_tilt_joint" type="revolute">
    	<parent link="head_tilt_link" />
    	<child link="upper_neck_link" />
    	<origin xyz="0 0 0.013" rpy="0 0 0" />
    	<axis xyz="0 1 0" />
    	<limit lower="-1.57" upper="1.57" effort="10" velocity="3" />
      	<dynamics damping="0.0"/>
	</joint>
  	
 	<joint name="upper_neck_joint" type="fixed">
    	<parent link="upper_neck_link" />
    	<child link="head_base_link" />
    	<origin xyz="0 0 0.040" rpy="0 0 0" />
	</joint>
	
	<joint name="head_base_joint" type="fixed">
    	<parent link="head_base_link" />
    	<child link="head_post_link" />
    	<origin xyz="0 0 0.016" rpy="0 0 0" />
	</joint>
	
	<joint name="head_joint" type="fixed">
    	<parent link="head_post_link" />
    	<child link="head_link" />
    	<origin xyz="0 0 0.0235" rpy="0 0 0" />
	</joint>
	
	<joint name="left_eye_joint" type="fixed">
    	<parent link="head_link" />
    	<child link="left_eye_link" />
    	<origin xyz="0.026 0.05 0" rpy="0 1.57 0" />
	</joint>
	
	<joint name="right_eye_joint" type="fixed">
    	<parent link="head_link" />
    	<child link="right_eye_link" />
    	<origin xyz="0.026 -0.05 0" rpy="0 1.57 0" />
	</joint>

	
	<!-- arm joints -->
	<joint name="wrist_tilt_joint" type="revolute">
	  <parent link="forearm_link" />
	  <child link="wrist_tilt_link" />
	  <axis xyz="0 1 0"/>
	  <origin xyz="0.255 0 0" rpy="0 0 0" />
	  <limit lower="-1.0" upper="1.0" effort="1.0" velocity="1.0" />
	</joint>
	
	<joint name="forearm_roll_joint" type="revolute">
	  <parent link="elbow_tilt_link" />
	  <child link="forearm_link" />
	  <axis xyz="0.135 0 0"/>
	  <origin xyz="0 0 0" rpy="0 0 0" />
	  <limit lower="-1.0" upper="1.0" effort="1.0" velocity="1.0" />
	</joint>
  
	<joint name="elbow_tilt_joint" type="revolute">
	  <parent link="upper_arm_link" />
	  <child link="elbow_tilt_link" />
	  <axis xyz="0 1 0"/>
	  <origin xyz="0.27 0 0" rpy="0 0 0" />
	  <limit lower="-1.0" upper="1.0" effort="1.0" velocity="1.0" />
	</joint>
	
	<joint name="upper_arm_roll_joint" type="revolute">
	  <parent link="shoulder_tilt_link" />
	  <child link="upper_arm_link" />
	  <axis xyz="0.135 0 0"/>
	  <origin xyz="0 0 0" rpy="0 0 0" />
	  <limit lower="-1.0" upper="1.0" effort="1.0" velocity="1.0" />
	</joint>

	<joint name="shoulder_tilt_joint" type="revolute">
	  <parent link="shoulder_tilt_support_link" />
	  <child link="shoulder_tilt_link" />
	  <axis xyz="0 1 0"/>
	  <origin xyz="0 0 -0.015" rpy="0 0 0" />
	  <limit lower="-1.0" upper="1.0" effort="1.0" velocity="1.0" />
	</joint>

	<joint name="shoulder_tilt_support_joint" type="fixed">
	  <parent link="shoulder_pan_link" />
	  <child link="shoulder_tilt_support_link" />
	  <origin xyz="0.0175 0.0 0" rpy="0 0 0" />
	</joint>
	
	<joint name="shoulder_pan_joint" type="revolute">
	  <parent link="shoulder_pan_support_link" />
	  <child link="shoulder_pan_link" />
	  <axis xyz="0.0 0 1"/>
	  <origin xyz="0.03 0 0" rpy="0 0 0" />
	  <limit lower="-1.0" upper="1.0" effort="1.0" velocity="1.0" />
	</joint>
	
	<joint name="shoulder_pan_support_joint" type="fixed">
	  <parent link="torso_link" />
	  <child link="shoulder_pan_support_link" />
	  <origin xyz="0.0325 -0.14 0.173" rpy="0 0 0" />
	</joint>
	
	<joint name="torso_joint" type="fixed">
	  <parent link="base_link" />
	  <child link="torso_link" />
	  <origin xyz="0 0 0.375" rpy="0 0 0" />
	</joint>
	



	


  
 	

	
	<gazebo reference="maggie">
  	</gazebo>
</robot>


